Workbook

Sheet 00_表紙
A1: APIC 2026年度設備投資 説明資料（費用対効果）
A2: 対象：APIC2026年度設備投資予算案 20260403版／APIC–TI契約は2029年3月末まで延長確定
A3: 1. 目的と方針
B4: 本当に必要な設備だけに投資する。選定理由は定性的な説明だけでなく、数字で確認できる費用対効果で示す。
B5: 全機種の購入を証明しようとしない。必須投資（安全・顧客要求・生産継続）／改善投資（省人・工数削減・レンタル削減・品質）／戦略・検証投資（将来案件・トライアル）に分ける。
B6: 説明の流れ：現状 → 課題 → 数値根拠 → 導入効果 → 費用対効果 → 投資妥当性 → 優先順位
B7: 新規条件：APICが50,000USDを負担。投資額はSuntoolを除き概ね4,000万円以下。
A9: 2. 主要数値（自動計算）
B10: 項目 | C10: USD | D10: 円 | E10: 備考
B11: 原案（優先①）合計 | C11: =02_投資総括!$H$26 -> 267343 | D11: =02_投資総括!$H$26*01_前提条件!$C$5 -> 42774880 | E11: 4,000万円を超過
B12: 調整案 合計 | C12: =02_投資総括!$J$26 -> 246923 | D12: =02_投資総括!$K$26 -> 39507680 | E12: スポットプレスは暫定台数（09）
B13: 上限（4,000万円）との差 | C13: =01_前提条件!$C$13/01_前提条件!$C$5-C12 -> 3077 | D13: =01_前提条件!$C$13-D12 -> 492320 | E13: ＋＝上限内
B14: APIC負担 | C14: =01_前提条件!$C$12 -> 50000 | D14: =01_前提条件!$C$12*01_前提条件!$C$5 -> 8000000 | E14: 対象機種・資産保有・償却処理は要確認
B15: TI負担（調整案−APIC負担） | C15: =C12-C14 -> 196923 | D15: =D12-D14 -> 31507680
A17: 3. シート構成
B18: シート | C18: 内容 | D18: 対応する要確認事項
B19: 01_前提条件 | C19: 為替・稼働日・電気単価・償却年数・APIC負担・上限などの前提（入力）
B20: 02_投資総括 | C20: 原案①と調整案の比較、投資区分、総額チェック、追加削減オプション | D20: ④・新規条件
B21: 03_要確認事項 | C21: 3/25要確認事項①〜⑦と新規条件への回答骨子・状態 | D21: 全体
B22: 04_機種別比較 | C22: 機種別：現状方式｜改善・代替案｜新設備案｜差分｜年間効果｜投資判断 | D22: 全体
B23: 05_ロック必要台数 | C23: ロックミシン必要台数（品種別標準台数→不足→借用・レンタル実績） | D23: ①
B24: 06_サーボ電力 | C24: サーボ vs クラッチの電力削減（副次効果）と品質・操作性 | D24: ①
B25: 07_省人効果 | C25: パターンシーマ／Spec-Dの省人工数（Before/After実測の入力表） | D25: ①
B26: 08_PS運用設計 | C26: パターンシーマの動線・人配置・縫製中の動き・測定計画 | D26: ②
B27: 09_スポットプレス | C27: スポットプレス必要台数の計算、更新分／純増分、証跡 | D27: ③
B28: 10_平プレス検証 | C28: 平プレスの精度検証（項目・方法・判定基準・頻度・担当） | D28: ⑤
B29: 11_縮絨試験 | C29: 縮絨機の検討ステップ（試験後に導入判断） | D29: ⑦
B30: 12_レンタル費 | C30: レンタル費実績と投資による回避可能額 | D30: ①
B31: 13_費用対効果PL | C31: 改善投資の年間純効果・回収年数、当年度P/L影響（ケースA/B） | D31: ①・新規条件
B32: 14_原案チェック | C32: 原案ファイルの不整合（提出前の修正候補）
A34: 4. 凡例
B35: 青字＋黄色 | C35: 入力値（工場データ・前提）。ここを変更すると全体が再計算される
B36: 黒字 | C36: 計算式
B37: 緑字 | C37: 他シートからの参照
B38: 灰色斜体 | C38: 記入例（合計に含めない）
B39: 薄緑 | C39: 主要な結果
A41: 5. 未確定データ（工場・関係部署から入手が必要）
B42: ・レンタル明細 2024・2026年（機種・型式・台数・期間・D/N・style/line）と、投資で回避できる部分
B43: ・パターンシーマ・Spec-DのBefore/After実測（工程秒・自動縫製秒・並行作業秒）と対象品番の年間数量
B44: ・スポットプレス旧型の台数・年式・修理可否、ライン別使用台数、ピーク需要、写真・ヒヤリハット
...

Sheet 01_前提条件
A1: 前提条件（全シート共通）
A2: 青字＋黄色セルが入力値。変更すると全シートが再計算される。
A3: 項目 | B3: 単位 | C3: 値 | D3: 出所・備考
A5: 為替レート | B5: 円/USD | C5: 160 | D5: 原案P30（円換算に使用）。原案O26は150円 → 提出前にTIJとレートを統一
A6: 年間稼働日 | B6: 日 | C6: 295 | D6: 技術打合せでの合意値
A7: 1日稼働時間 | B7: 時間 | C7: 8 | D7: 技術打合せでの合意値
A8: 有効稼働率 | B8: % | C8: 1 | D8: 工程秒が標準時間（余裕込み）なら100%。正味時間で測る場合は工場の実効率を入力
A9: 1人年間有効稼働秒 | B9: 秒 | C9: =C6*C7*3600*C8 -> 8496000 | D9: 年間稼働日×1日稼働時間×3600×有効稼働率（省人工数の分母）
A10: 電気単価 | B10: USD/kWh | C10: 0.08 | D10: 技術打合せでの合意値
A11: 償却年数 | B11: 年 | C11: 7 | D11: 原案U列（=金額÷7）と同じ
A12: APIC負担額 | B12: USD | C12: 50000 | D12: 新規条件：APICが投資額のうち50,000USDを負担（対象機種・資産保有・償却処理は要確認）
A13: 投資額上限目標（Suntool除く） | B13: 円 | C13: 40000000 | D13: 佐藤さん希望：Suntoolを除き概ね4,000万円以下。20260403版リストにSuntoolは含まれていない
A14: 1人当たり年間人件費 | B14: USD/人年 | D14: APIC人事データで入力。未入力の間は省人効果を『人工』のみで表示し、金額効果は0とする
A15: 通常稼働ライン数 | B15: ライン | C15: 31 | D15: APIC通常31ライン
A16: ピークライン数 | B16: ライン | C16: 35 | D16: 繁忙期34〜35ライン（軽量品6,000秒未満は32人ラインを16人×2に分割）→ 上限35で試算

Sheet 02_投資総括
A1: 投資総括：原案（優先①）と調整案
A2: 調整案台数（I列）とAPIC負担（N列）が入力欄。スポットプレスの台数は09シートの計算結果を自動参照。単価は原案L列（VA後）、L列が空欄の機種はK列（概算）。
A4: 原案No. | B4: 設備名 | C4: メーカー・品番 | D4: 投資区分 | E4: 優先順位 | F4: 単価(USD) | G4: 原案①台数 | H4: 原案①金額(USD) | I4: 調整案台数 | J4: 調整案金額(USD) | K4: 調整案金額(円) | L4: 増減(USD) | M4: 調整理由・判断 | N4: APIC負担(USD) | O4: TI負担(USD) | P4: TI年間償却(円) | Q4: 根拠シート
A5: 1 | B5: 2本針オーバーロック（サーボ・自動糸切り） | C5: Juki MO-6814 | D5: 必須（生産継続） | E5: 3 | F5: 980 | G5: 5 | H5: =F5*G5 -> 4900 | I5: 5 | J5: =F5*I5 -> 4900 | K5: =J5*01_前提条件!$C$5 -> 784000 | L5: =J5-H5 -> 0 | M5: ピーク不足26台（05）。故障4台の更新＋純増1台。残る不足は第2工場借用で対応 | O5: =J5-N5 -> 4900 | P5: =O5*01_前提条件!$C$5/01_前提条件!$C$11 -> 112000 | Q5: 05_ロック必要台数
A6: 2 | B6: 2本針インターロック（サーボ・自動糸切り） | C6: Juki MO-6816 | D6: 必須（生産継続） | E6: 3 | F6: 1150 | G6: 2 | H6: =F6*G6 -> 2300 | I6: 2 | J6: =F6*I6 -> 2300 | K6: =J6*01_前提条件!$C$5 -> 368000 | L6: =J6-H6 -> 0 | M6: ピーク不足6台（05）。2台購入、残りは借用で対応 | O6: =J6-N6 -> 2300 | P6: =O6*01_前提条件!$C$5/01_前提条件!$C$11 -> 52571.429 | Q6: 05_ロック必要台数
A7: 3 | B7: 眠り穴かがりミシン | C7: Hikari HBH-1790E-S | D7: 見送り | E7: - | F7: 2376 | G7: 0 | H7: =F7*G7 -> 0 | I7: 0 | J7: =F7*I7 -> 0 | K7: =J7*01_前提条件!$C$5 -> 0 | L7: =J7-H7 -> 0 | M7: 原案でも優先②のみ。2026年度は計上しない | O7: =J7-N7 -> 0 | P7: =O7*01_前提条件!$C$5/01_前提条件!$C$11 -> 0
A8: 4 | B8: パターンシーマ 中型 60×40 | C8: Hikari HMS-6040 | D8: 改善 | E8: 4 | F8: 4450 | G8: 3 | H8: =F8*G8 -> 13350 | I8: 3 | J8: =F8*I8 -> 13350 | K8: =J8*01_前提条件!$C$5 -> 2136000 | L8: =J8-H8 -> 0 | M8: GW系ポケットファスナーのPS指示。運用設計（08）とセットで導入、効果は07で実測 | O8: =J8-N8 -> 13350 | P8: =O8*01_前提条件!$C$5/01_前提条件!$C$11 -> 305142.86 | Q8: 07_省人効果
A9: 5 | B9: パターンシーマ 大型 130×95（360度回転） | C9: Hikari HMS-13095A/RND | D9: 改善 | E9: 4 | F9: 6500 | G9: 6 | H9: =F9*G9 -> 39000 | I9: 4 | J9: =F9*I9 -> 26000 | K9: =J9*01_前提条件!$C$5 -> 4160000 | L9: =J9-H9 -> -13000 | M9: 6→4台に段階導入。数値で確認できる効果はレンタル3,016.54＋キルティング外注約3,000USD/年。省人実測後に追加判断 | O9: =J9-N9 -> 26000 | P9: =O9*01_前提条件!$C$5/01_前提条件!$C$11 -> 594285.71 | Q9: 07_省人効果
A10: 6 | B10: 本縫針送りミシン | C10: DUMA DM1968L-NF | D10: 必須（生産継続） | E10: 5 | F10: 880 | G10: 10 | H10: =F10*G10 -> 8800 | I10: 10 | J10: =F10*I10 -> 8800 | K10: =J10*01_前提条件!$C$5 -> 1408000 | L10: =J10-H10 -> 0 | M10: 各ライン1台必要（31台）に対し現有17台。レンタル削減額は2025実績で再確認（14参照） | O10: =J10-N10 -> 8800 | P10: =O10*01_前提条件!$C$5/01_前提条件!$C$11 -> 201142.86 | Q10: 14_原案チェック
A11: 7 | B11: シームシーリング Spec-D（ロングアーム） | C11: H&H AI-002 spec-D | D11: 改善 | E11: 7 | F11: 9700 | G11: 3 | H11: =F11*G11 -> 29100 | I11: 2 | J11: =F11*I11 -> 19400 | K11: =J11*01_前提条件!$C$5 -> 3104000 | L11: =J11-H11 -> -9700 | M11: 3→2台。2名体制→1名化の省人効果を07で実測し、効果確認後に追加 | O11: =J11-N11 -> 19400 | P11: =O11*01_前提条件!$C$5/01_前提条件!$C$11 -> 443428.57 | Q11: 07_省人効果
A12: 8 | B12: シームシーリング Spec-IJ（曲線部） | C12: H&H AI-129 spec-IJ | D12: 戦略／検証 | E12: 9 | F12: 6800 | G12: 1 | H12: =F12*G12 -> 6800 | I12: 1 | J12: =F12*I12 -> 6800 | K12: =J12*01_前提条件!$C$5 -> 1088000 | L12: =J12-H12 -> 0 | M12: 評価用1台（量産ライン配置、剥離不良率で評価） | O12: =J12-N12 -> 6800 | P12: =O12*01_前提条件!$C$5/01_前提条件!$C$11 -> 155428.57 | Q12: 04_機種別比較
A13: 9 | B13: 温冷プレス 60×12cm | C13: H&H CSL-201 | D13: 必須（生産継続） | E13: 6 | F13: 4150 | G13: 6 | H13: =F13*G13 -> 24900 | I13: 6 | J13: =F13*I13 -> 24900 | K13: =J13*01_前提条件!$C$5 -> 3984000 | L13: =J13-H13 -> 0 | M13: 現有30×10cm 26台で不足。工程秒約半減（原案記載）→ 対象数量で効果算出 | O13: =J13-N13 -> 24900 | P13: =O13*01_前提条件!$C$5/01_前提条件!$C$11 -> 569142.86 | Q13: 13_費用対効果PL
A14: 10 | B14: 平プレス 125×83cm | C14: H&H CS-691 | D14: 改善 | E14: 8 | F14: 13000 | G14: 2 | H14: =F14*G14 -> 26000 | I14: 1 | J14: =F14*I14 -> 13000 | K14: =J14*01_前提条件!$C$5 -> 2080000 | L14: =J14-H14 -> -13000 | M14: 2→1台。精度検証方法（10）で効果確認後に追加 | O14: =J14-N14 -> 13000 | P14: =O14*01_前提条件!$C$5/01_前提条件!$C$11 -> 297142.86 | Q14: 10_平プレス検証
A15: 11 | B15: スポットプレス 30×10cm（安全装置付） | C15: PTTG MEN/PTTG 300X100 | D15: 必須（安全） | E15: 1 | F15: 764 | G15: 10 | H15: =F15*G15 -> 7640 | I15: =09_スポットプレス!$C$20 -> 30 | J15: =F15*I15 -> 22920 | K15: =J15*01_前提条件!$C$5 -> 3667200 | L15: =J15-H15 -> 15280 | M15: 安全装置なし旧型を全数入替。台数は09の計算結果（暫定：必要45台−新型現有15台） | O15: =J15-N15 -> 22920 | P15: =O15*01_前提条件!$C$5/01_前提条件!$C$11 -> 523885.71 | Q15: 09_スポットプレス
A16: 12 | B16: Nawon温冷プレス（フロントジッパー） | C16: Nawon HTM-8749 | D16: 必須（顧客要求） | E16: 2 | F16: 19980 | G16: 2 | H16: =F16*G16 -> 39960 | I16: 2 | J16: =F16*I16 -> 39960 | K16: =J16*01_前提条件!$C$5 -> 6393600 | L16: =J16-H16 -> 0 | M16: 26FW GW要請（SW1課より4種導入要望） | O16: =J16-N16 -> 39960 | P16: =O16*01_前提条件!$C$5/01_前提条件!$C$11 -> 913371.43 | Q16: 04_機種別比較
A17: 13 | B17: Nawon温冷プレス（袖） | C17: Nawon HTM-8739 | D17: 必須（顧客要求） | E17: 2 | F17: 19980 | G17: 1 | H17: =F17*G17 -> 19980 | I17: 1 | J17: =F17*I17 -> 19980 | K17: =J17*01_前提条件!$C$5 -> 3196800 | L17: =J17-H17 -> 0 | M17: 同上 | O17: =J17-N17 -> 19980 | P17: =O17*01_前提条件!$C$5/01_前提条件!$C$11 -> 456685.71 | Q17: 04_機種別比較
A18: 14 | B18: Nawon温冷プレス（ヘムライン） | C18: Nawon HTM-8709 | D18: 必須（顧客要求） | E18: 2 | F18: 19980 | G18: 1 | H18: =F18*G18 -> 19980 | I18: 1 | J18: =F18*I18 -> 19980 | K18: =J18*01_前提条件!$C$5 -> 3196800 | L18: =J18-H18 -> 0 | M18: 同上。ストレート型はH&H CSL-207（10,500USD）で代替可能性あり → 追加削減オプション | O18: =J18-N18 -> 19980 | P18: =O18*01_前提条件!$C$5/01_前提条件!$C$11 -> 456685.71 | Q18: 04_機種別比較
A19: 15 | B19: Nawon温冷プレス（カーブ） | C19: Nawon HTM-8601 | D19: 必須（顧客要求） | E19: 2 | F19: 18333 | G19: 1 | H19: =F19*G19 -> 18333 | I19: 1 | J19: =F19*I19 -> 18333 | K19: =J19*01_前提条件!$C$5 -> 2933280 | L19: =J19-H19 -> 0 | M19: 同上（2025年度1台導入済） | O19: =J19-N19 -> 18333 | P19: =O19*01_前提条件!$C$5/01_前提条件!$C$11 -> 419040 | Q19: 04_機種別比較
A20: 16 | B20: 自動延反機 | C20: NCA ES-8 | D20: 見送り | E20: - | F20: 50980 | G20: 0 | H20: =F20*G20 -> 0 | I20: 0 | J20: =F20*I20 -> 0 | K20: =J20*01_前提条件!$C$5 -> 0 | L20: =J20-H20 -> 0 | M20: 2/25打合せで26年度見送り | O20: =J20-N20 -> 0 | P20: =O20*01_前提条件!$C$5/01_前提条件!$C$11 -> 0
A21: 17 | B21: ダウン充填機 | C21: Shenghong 1184RM10 | D21: 見送り | E21: - | F21: 9800 | G21: 0 | H21: =F21*G21 -> 0 | I21: 0 | J21: =F21*I21 -> 0 | K21: =J21*01_前提条件!$C$5 -> 0 | L21: =J21-H21 -> 0 | M21: 3/25打合せで見送り（現有4台で最大10ライン対応可） | O21: =J21-N21 -> 0 | P21: =O21*01_前提条件!$C$5/01_前提条件!$C$11 -> 0
A22: 18 | B22: 超音波溶着機 35Hz | C22: H&H US-512 | D22: 戦略／検証 | E22: 10 | F22: 6300 | G22: 1 | H22: =F22*G22 -> 6300 | I22: 1 | J22: =F22*I22 -> 6300 | K22: =J22*01_前提条件!$C$5 -> 1008000 | L22: =J22-H22 -> 0 | M22: トライアル（サンプル試作で評価、営業提案の幅を広げる） | O22: =J22-N22 -> 6300 | P22: =O22*01_前提条件!$C$5/01_前提条件!$C$11 -> 144000 | Q22: 04_機種別比較
A23: 18※ | B23: テーピングマシン（比較検証用） | C23: Nawon HTM-5588 SSF-LDi | D23: 見送り | E23: - | F23: 11100 | G23: 0 | H23: =F23*G23 -> 0 | I23: 0 | J23: =F23*I23 -> 0 | K23: =J23*01_前提条件!$C$5 -> 0 | L23: =J23-H23 -> 0 | M23: 原案でも優先②のみ。※原案でNo.18が重複 | O23: =J23-N23 -> 0 | P23: =O23*01_前提条件!$C$5/01_前提条件!$C$11 -> 0
A24: 19 | B24: テーピングマシン（比較検証用） | C24: Nawon HTM-3833 SSF-Ldi | D24: 見送り | E24: - | F24: 9130 | G24: 0 | H24: =F24*G24 -> 0 | I24: 0 | J24: =F24*I24 -> 0 | K24: =J24*01_前提条件!$C$5 -> 0 | L24: =J24-H24 -> 0 | M24: 原案でも優先②のみ | O24: =J24-N24 -> 0 | P24: =O24*01_前提条件!$C$5/01_前提条件!$C$11 -> 0
A25: 20 | B25: 刺繍機（20頭） | C25: TAJIMA TMCP-V0920F | D25: 見送り | E25: - | F25: 81000 | G25: 0 | H25: =F25*G25 -> 0 | I25: 0 | J25: =F25*I25 -> 0 | K25: =J25*01_前提条件!$C$5 -> 0 | L25: =J25-H25 -> 0 | M25: 原案でも優先②のみ | O25: =J25-N25 -> 0 | P25: =O25*01_前提条件!$C$5/01_前提条件!$C$11 -> 0
A26: 合計 | G26: =SUM(G5:G25) -> 54 | H26: =SUM(H5:H25) -> 267343 | I26: =SUM(I5:I25) -> 70 | J26: =SUM(J5:J25) -> 246923 | K26: =SUM(K5:K25) -> 39507680 | L26: =SUM(L5:L25) -> -20420 | N26: =SUM(N5:N25) -> 0 | O26: =SUM(O5:O25) -> 246923 | P26: =SUM(P5:P25) -> 5643954.3
A28: 総額チェック
B29: 項目 | C29: USD | D29: 円 | E29: 判定・備考
B30: 原案（優先①）合計 | C30: =H26 -> 267343 | D30: =H26*01_前提条件!$C$5 -> 42774880 | E30: 原案ファイルのN25（267,343USD）と一致
B31: 調整案 合計 | C31: =J26 -> 246923 | D31: =K26 -> 39507680
B32: 投資額上限目標（Suntool除く） | C32: =01_前提条件!$C$13/01_前提条件!$C$5 -> 250000 | D32: =01_前提条件!$C$13 -> 40000000 | E32: 前提条件C13
B33: 上限との差（＋＝余裕） | C33: =C32-C31 -> 3077 | D33: =D32-D31 -> 492320 | E33: =IF(D33>=0,"上限内","上限超過：追加削減オプションを検討") -> 上限内
B34: APIC負担（前提） | C34: =01_前提条件!$C$12 -> 50000 | D34: =01_前提条件!$C$12*01_前提条件!$C$5 -> 8000000 | E34: =IF(N26=01_前提条件!$C$12,"機種別配分 OK","機種別配分 未確定（N列に入力：未割当 "&TEXT(01_前提条件!$C$12-N26,"#,##0")&" USD）") -> 機種別配分 未確定（N列に入力：未割当 50,000 USD）
B35: TI負担（調整案−APIC負担） | C35: =C31-C34 -> 196923 | D35: =D31-D34 -> 31507680 | E35: APIC負担分の資産保有・償却処理は要確認（13参照）
A37: 投資区分別（調整案）
B38: 投資区分 | C38: 調整案金額(USD) | D38: 構成比 | E38: 考え方
B39: 必須（安全） | C39: =SUMIF($D$5:$D$25,B39,$J$5:$J$25) -> 22920 | D39: =IF($J$26=0,0,C39/$J$26) -> 0.092822459 | E39: 安全リスクの解消。ROIではなく安全で判断
B40: 必須（顧客要求） | C40: =SUMIF($D$5:$D$25,B40,$J$5:$J$25) -> 98253 | D40: =IF($J$26=0,0,C40/$J$26) -> 0.39790947 | E40: 顧客指示・要請への対応（受注維持）
B41: 必須（生産継続） | C41: =SUMIF($D$5:$D$25,B41,$J$5:$J$25) -> 40900 | D41: =IF($J$26=0,0,C41/$J$26) -> 0.16563868 | E41: 機材不足の解消（借用・レンタル依存からの脱却）
B42: 改善 | C42: =SUMIF($D$5:$D$25,B42,$J$5:$J$25) -> 71750 | D42: =IF($J$26=0,0,C42/$J$26) -> 0.29057641 | E42: 省人・工数削減・レンタル/外注削減・品質。数値効果で判断し段階導入
B43: 戦略／検証 | C43: =SUMIF($D$5:$D$25,B43,$J$5:$J$25) -> 13100 | D43: =IF($J$26=0,0,C43/$J$26) -> 0.053052976 | E43: 将来案件・トライアル。少数導入して評価
...

Sheet 05_ロック必要台数
A1: ロックミシン 必要台数と不足（No.1・No.2）
A2: 不足は試算上だけではなく、第2工場からの借用および外部レンタルで実運用上すでに顕在化している。
A3: 1. 品種別 標準使用台数（1ライン当たり）
A4: 品種 | B4: オーバーロック | C4: インターロック | D4: 主な用途
A5: 通常品 | B5: 3 | C5: 2 | D5: OL：パーツ縫製・ポケット袋布・収納袋／IL：袖下・脇・フード
A6: Seam Jacket | B6: 3 | C6: 2 | D6: 同上
A7: Down Jacket | B7: 3 | C7: 2 | D7: 同上
A8: ウィンドブレーカー・1枚もの軽量品 | B8: 4 | C8: 2 | D8: 軽量品は全パーツの端処理をOLで行うため1台多い
A10: 2. 前提
A11: 項目 | B11: 値 | D11: 備考
A12: 通常稼働ライン数 | B12: =01_前提条件!$C$15 -> 31 | D12: 前提条件
A13: ピークライン数 | B13: =01_前提条件!$C$16 -> 35 | D13: 前提条件
A14: OL3台ラインの構成比 | B14: 0.8 | D14: 製品構成の想定（通常品・Seam・Down）
A15: OL4台ラインの構成比 | B15: =1-B14 -> 0.2 | D15: 軽量品
A16: 平均OL台数／ライン | B16: =B14*3+B15*4 -> 3.2 | D16: 80%×3台＋20%×4台＝3.2台（原案R4の『平均4台』は過大 → 修正）
A17: IL台数／ライン | B17: 2 | D17: 全品種2台
A19: 3. 必要台数・実稼働・不足
A20: 項目 | B20: オーバーロック | C20: インターロック | D20: 計算式・備考
A21: 現有台数 | B21: 102 | C21: 68 | D21: 原案S4・S5
A22: 老朽化・重大故障（修理復旧不可、実稼働対象外） | B22: 4 | C22: 0 | D22: OL4台は修理復旧不可。ILは0〜1台（実稼働63〜64台）→ 要確認
A23: サンプルライン固定 | B23: 12 | C23: 4
A24: 生産用 実稼働可能台数 | B24: =B21-B22-B23 -> 86 | C24: =C21-C22-C23 -> 64 | D24: 現有−故障−サンプル固定
A25: 通常期 必要台数（31ライン） | B25: =ROUNDUP(B12*B16,0) -> 100 | C25: =B12*B17 -> 62 | D25: ライン数×平均台数（端数切上げ）
A26: ピーク 必要台数（35ライン） | B26: =ROUNDUP(B13*B16,0) -> 112 | C26: =B13*B17 -> 70
A27: 通常期 不足 | B27: =MAX(0,B25-B24) -> 14 | C27: =MAX(0,C25-C24) -> 0
A28: ピーク 不足（実質不足） | B28: =MAX(0,B26-B24) -> 26 | C28: =MAX(0,C26-C24) -> 6 | D28: この不足を借用・レンタルで埋めている
A30: 4. 実運用での顕在化（証跡）
A31: 項目 | B31: 台数 | D31: 備考
A32: 繁忙期 APIC第2工場から借用 | B32: 10 | D32: 10〜12台（下限で計上）。先方の受注増で継続借用は困難になる見込み。機種内訳（OL/IL）は要確認
A33: 外部レンタル実績（2024年10〜12月） | B33: 10 | D33: 約10台。金額はD/Nから12_レンタル費へ入力
A35: 5. 購入後の不足
A36: 項目 | B36: オーバーロック | C36: インターロック | D36: 備考
A37: 調整案 購入台数 | B37: =02_投資総括!$I$5 -> 5 | C37: =02_投資総括!$I$6 -> 2 | D37: 02_投資総括から参照
A38: うち 更新分（故障機の置換） | B38: =MIN(B37,B22) -> 4 | C38: =MIN(C37,C22) -> 0
A39: うち 純増分 | B39: =B37-B38 -> 1 | C39: =C37-C38 -> 2
A40: 購入後 ピーク不足 | B40: =MAX(0,B28-B37) -> 21 | C40: =MAX(0,C28-C37) -> 4 | D40: 残りは第2工場借用で対応（借用不可の場合は原案優先②5台＋3台を条件付き追加枠とする）
A42: 説明文案：『不足は試算上だけではなく、繁忙期に第2工場から10〜12台を借用し、2024年10〜12月には約10台を外部レンタルしており、実運用上すでに顕在化している。』

Sheet 06_サーボ電力
A1: ロックミシン サーボモーター vs クラッチモーター
A2: 電力削減は副次効果。主目的は機材不足の解消と、即停止による縫いズレ低減（品質・操作性）。
A3: 1. 消費電力の前提
A4: 項目 | B4: クラッチ | C4: サーボ | D4: 備考
A5: 定格出力 (W) | B5: 400 | C5: 550 | D5: サーボは定格が大きいがペダル操作時のみ回転
A6: 縫製時 (W) | B6: 350 | C6: 200
A7: 非縫製時 (W) | B7: 250 | C7: 2 | D7: クラッチは縫っていない間も空転、サーボは待機電力のみ
A8: 1日稼働時間 (h) | B8: =01_前提条件!$C$7 -> 8 | C8: =B8 -> 8 | D8: 前提条件
A9: うち縫製時間 (h) | B9: 4 | C9: =B9 -> 4 | D9: 8時間中4時間縫製 → クラッチ2.400kWh/日・サーボ0.808kWh/日（従来試算と一致）
A10: 非縫製時間 (h) | B10: =B8-B9 -> 4 | C10: =C8-C9 -> 4
A12: 2. 削減効果
A13: 項目 | B13: 値 | D13: 計算式
A14: クラッチ 消費電力 (kWh/日) | B14: =(B6*B9+B7*B10)/1000 -> 2.4 | D14: (縫製W×縫製h＋非縫製W×非縫製h)÷1000
A15: サーボ 消費電力 (kWh/日) | B15: =(C6*C9+C7*C10)/1000 -> 0.808
A16: 削減 (kWh/日・台) | B16: =B14-B15 -> 1.592
A17: 年間削減 (kWh/年・台) | B17: =B16*01_前提条件!$C$6 -> 469.64 | D17: ×年間稼働日
A18: 年間削減 (USD/年・台) | B18: =B17*01_前提条件!$C$10 -> 37.5712 | D18: ×電気単価
A19: 参考：5台 (USD/年) | B19: =B18*5 -> 187.856 | D19: 原案No.1の5台
A20: 調整案 対象台数（OL＋IL） | B20: =02_投資総括!$I$5+02_投資総括!$I$6 -> 7 | D20: 新機がクラッチ機の稼働を置き換える前提（借用・レンタル機はクラッチ機）
A21: 年間削減 合計 (USD/年) | B21: =B18*B20 -> 262.9984 | D21: 13_費用対効果PLへ連携
A23: 3. 品質・操作性（主効果）
A24: 項目 | B24: クラッチモーター（現状） | C24: サーボモーター（新） | D24: 品質への影響
A25: 停止 | B25: ペダルを離しても惰性回転で数針進む | C25: ペダルOFFで即停止 | D25: 曲線部で止めて向きを直す作業の精度が上がる
A26: 曲線部の微調整 | B26: 微調整が難しく熟練に依存 | C26: 低速・針単位の調整が容易 | D26: 縫いズレ減少、品質安定
A27: 属人性 | B27: 熟練者でないと品質がばらつく | C27: 操作が標準化しやすい | D27: 習熟期間短縮、不良低減
A28: 糸切り | B28: 手作業 | C28: 自動糸切り | D28: 工程内の付帯作業削減

Sheet 07_省人効果
A1: 省人効果：パターンシーマ（No.4・5）／Spec-D（No.7）
A2: 省人化＝人員削減ではない。工程秒削減 → 必要工数削減 → 必要人員減 → 余力人員の再配置 → 工場全体の生産性向上（例：30人必要→28人で同じ生産量→2人を他工程へ）。
A3: 1人年間有効稼働秒 | E3: =01_前提条件!$C$9 -> 8496000 | F3: 年間削減工数（秒）＝（Before工程秒−After工程秒）×年間生産数量 ／ 省人工数＝年間削減工数÷1人年間有効稼働秒
A4: ※全ケースでサイクルが短くなるわけではない（同等・数秒遅いケースあり）。サイクル基準と『作業者拘束時間』基準の両方を表示し、拘束時間・工程集約・品質・習熟で評価する。黄色セルに工場の実測raw dataを入力。
A5: 1. パターンシーマ：手作業 → 改善治具＋1本針 → パターンシーマ（同一工程の3方式比較）
A6: 対象 | F6: 手作業 | H6: 治具＋1本針 | J6: パターンシーマ | O6: 差分・効果（手作業比） | V6: 判定 | W6: 定性効果（実測）
A7: No | B7: 顧客 | C7: 部位・工程 | D7: 機種(大/中) | E7: 年間生産数量(枚) | F7: 工程数 | G7: 工程秒 | H7: 工程数 | I7: 工程秒 | J7: 工程数 | K7: サイクル秒 | L7: うち自動縫製秒 | M7: 自動縫製中の並行作業秒(実測) | N7: 作業者拘束秒 | O7: 工程数削減 | P7: サイクル差(秒) | Q7: 拘束時間差(秒) | R7: 年間削減工数(秒)サイクル基準 | S7: 年間削減工数(秒)拘束基準 | T7: 省人工数(人)サイクル基準 | U7: 省人工数(人)拘束基準 | V7: 判定 | W7: 習熟日数 手作業 | X7: 習熟日数 PS | Y7: 不良率 手作業 | Z7: 不良率 PS
A8: 記入例 | B8: 例 | C8: ファスナー（例） | D8: 中 | E8: 10000 | F8: 6 | G8: 340 | H8: 3 | I8: 330 | J8: 2 | K8: 310 | L8: 180 | M8: 120 | N8: =IF(K8="","",K8-N(M8)) -> 190 | O8: =IF(OR(F8="",J8=""),"",F8-J8) -> 4 | P8: =IF(OR(G8="",K8=""),"",G8-K8) -> 30 | Q8: =IF(OR(G8="",N8=""),"",G8-N8) -> 150 | R8: =IF(OR(E8="",P8=""),"",P8*E8) -> 300000 | S8: =IF(OR(E8="",Q8=""),"",Q8*E8) -> 1500000 | T8: =IF(R8="","",R8/01_前提条件!$C$9) -> 0.035310734 | U8: =IF(S8="","",S8/01_前提条件!$C$9) -> 0.17655367 | V8: =IF(P8="","",IF(P8>0,"サイクル短縮",IF(P8=0,"サイクル同等：拘束・品質で評価","サイクル増：拘束・品質で評価"))) -> サイクル短縮
A9: 1 | N9: =IF(K9="","",K9-N(M9)) | O9: =IF(OR(F9="",J9=""),"",F9-J9) | P9: =IF(OR(G9="",K9=""),"",G9-K9) | Q9: =IF(OR(G9="",N9=""),"",G9-N9) | R9: =IF(OR(E9="",P9=""),"",P9*E9) | S9: =IF(OR(E9="",Q9=""),"",Q9*E9) | T9: =IF(R9="","",R9/01_前提条件!$C$9) | U9: =IF(S9="","",S9/01_前提条件!$C$9) | V9: =IF(P9="","",IF(P9>0,"サイクル短縮",IF(P9=0,"サイクル同等：拘束・品質で評価","サイクル増：拘束・品質で評価")))
A10: 2 | N10: =IF(K10="","",K10-N(M10)) | O10: =IF(OR(F10="",J10=""),"",F10-J10) | P10: =IF(OR(G10="",K10=""),"",G10-K10) | Q10: =IF(OR(G10="",N10=""),"",G10-N10) | R10: =IF(OR(E10="",P10=""),"",P10*E10) | S10: =IF(OR(E10="",Q10=""),"",Q10*E10) | T10: =IF(R10="","",R10/01_前提条件!$C$9) | U10: =IF(S10="","",S10/01_前提条件!$C$9) | V10: =IF(P10="","",IF(P10>0,"サイクル短縮",IF(P10=0,"サイクル同等：拘束・品質で評価","サイクル増：拘束・品質で評価")))
A11: 3 | N11: =IF(K11="","",K11-N(M11)) | O11: =IF(OR(F11="",J11=""),"",F11-J11) | P11: =IF(OR(G11="",K11=""),"",G11-K11) | Q11: =IF(OR(G11="",N11=""),"",G11-N11) | R11: =IF(OR(E11="",P11=""),"",P11*E11) | S11: =IF(OR(E11="",Q11=""),"",Q11*E11) | T11: =IF(R11="","",R11/01_前提条件!$C$9) | U11: =IF(S11="","",S11/01_前提条件!$C$9) | V11: =IF(P11="","",IF(P11>0,"サイクル短縮",IF(P11=0,"サイクル同等：拘束・品質で評価","サイクル増：拘束・品質で評価")))
A12: 4 | N12: =IF(K12="","",K12-N(M12)) | O12: =IF(OR(F12="",J12=""),"",F12-J12) | P12: =IF(OR(G12="",K12=""),"",G12-K12) | Q12: =IF(OR(G12="",N12=""),"",G12-N12) | R12: =IF(OR(E12="",P12=""),"",P12*E12) | S12: =IF(OR(E12="",Q12=""),"",Q12*E12) | T12: =IF(R12="","",R12/01_前提条件!$C$9) | U12: =IF(S12="","",S12/01_前提条件!$C$9) | V12: =IF(P12="","",IF(P12>0,"サイクル短縮",IF(P12=0,"サイクル同等：拘束・品質で評価","サイクル増：拘束・品質で評価")))
A13: 5 | N13: =IF(K13="","",K13-N(M13)) | O13: =IF(OR(F13="",J13=""),"",F13-J13) | P13: =IF(OR(G13="",K13=""),"",G13-K13) | Q13: =IF(OR(G13="",N13=""),"",G13-N13) | R13: =IF(OR(E13="",P13=""),"",P13*E13) | S13: =IF(OR(E13="",Q13=""),"",Q13*E13) | T13: =IF(R13="","",R13/01_前提条件!$C$9) | U13: =IF(S13="","",S13/01_前提条件!$C$9) | V13: =IF(P13="","",IF(P13>0,"サイクル短縮",IF(P13=0,"サイクル同等：拘束・品質で評価","サイクル増：拘束・品質で評価")))
A14: 6 | N14: =IF(K14="","",K14-N(M14)) | O14: =IF(OR(F14="",J14=""),"",F14-J14) | P14: =IF(OR(G14="",K14=""),"",G14-K14) | Q14: =IF(OR(G14="",N14=""),"",G14-N14) | R14: =IF(OR(E14="",P14=""),"",P14*E14) | S14: =IF(OR(E14="",Q14=""),"",Q14*E14) | T14: =IF(R14="","",R14/01_前提条件!$C$9) | U14: =IF(S14="","",S14/01_前提条件!$C$9) | V14: =IF(P14="","",IF(P14>0,"サイクル短縮",IF(P14=0,"サイクル同等：拘束・品質で評価","サイクル増：拘束・品質で評価")))
A15: 7 | N15: =IF(K15="","",K15-N(M15)) | O15: =IF(OR(F15="",J15=""),"",F15-J15) | P15: =IF(OR(G15="",K15=""),"",G15-K15) | Q15: =IF(OR(G15="",N15=""),"",G15-N15) | R15: =IF(OR(E15="",P15=""),"",P15*E15) | S15: =IF(OR(E15="",Q15=""),"",Q15*E15) | T15: =IF(R15="","",R15/01_前提条件!$C$9) | U15: =IF(S15="","",S15/01_前提条件!$C$9) | V15: =IF(P15="","",IF(P15>0,"サイクル短縮",IF(P15=0,"サイクル同等：拘束・品質で評価","サイクル増：拘束・品質で評価")))
A16: 8 | N16: =IF(K16="","",K16-N(M16)) | O16: =IF(OR(F16="",J16=""),"",F16-J16) | P16: =IF(OR(G16="",K16=""),"",G16-K16) | Q16: =IF(OR(G16="",N16=""),"",G16-N16) | R16: =IF(OR(E16="",P16=""),"",P16*E16) | S16: =IF(OR(E16="",Q16=""),"",Q16*E16) | T16: =IF(R16="","",R16/01_前提条件!$C$9) | U16: =IF(S16="","",S16/01_前提条件!$C$9) | V16: =IF(P16="","",IF(P16>0,"サイクル短縮",IF(P16=0,"サイクル同等：拘束・品質で評価","サイクル増：拘束・品質で評価")))
A17: 9 | N17: =IF(K17="","",K17-N(M17)) | O17: =IF(OR(F17="",J17=""),"",F17-J17) | P17: =IF(OR(G17="",K17=""),"",G17-K17) | Q17: =IF(OR(G17="",N17=""),"",G17-N17) | R17: =IF(OR(E17="",P17=""),"",P17*E17) | S17: =IF(OR(E17="",Q17=""),"",Q17*E17) | T17: =IF(R17="","",R17/01_前提条件!$C$9) | U17: =IF(S17="","",S17/01_前提条件!$C$9) | V17: =IF(P17="","",IF(P17>0,"サイクル短縮",IF(P17=0,"サイクル同等：拘束・品質で評価","サイクル増：拘束・品質で評価")))
A18: 10 | N18: =IF(K18="","",K18-N(M18)) | O18: =IF(OR(F18="",J18=""),"",F18-J18) | P18: =IF(OR(G18="",K18=""),"",G18-K18) | Q18: =IF(OR(G18="",N18=""),"",G18-N18) | R18: =IF(OR(E18="",P18=""),"",P18*E18) | S18: =IF(OR(E18="",Q18=""),"",Q18*E18) | T18: =IF(R18="","",R18/01_前提条件!$C$9) | U18: =IF(S18="","",S18/01_前提条件!$C$9) | V18: =IF(P18="","",IF(P18>0,"サイクル短縮",IF(P18=0,"サイクル同等：拘束・品質で評価","サイクル増：拘束・品質で評価")))
A19: 11 | N19: =IF(K19="","",K19-N(M19)) | O19: =IF(OR(F19="",J19=""),"",F19-J19) | P19: =IF(OR(G19="",K19=""),"",G19-K19) | Q19: =IF(OR(G19="",N19=""),"",G19-N19) | R19: =IF(OR(E19="",P19=""),"",P19*E19) | S19: =IF(OR(E19="",Q19=""),"",Q19*E19) | T19: =IF(R19="","",R19/01_前提条件!$C$9) | U19: =IF(S19="","",S19/01_前提条件!$C$9) | V19: =IF(P19="","",IF(P19>0,"サイクル短縮",IF(P19=0,"サイクル同等：拘束・品質で評価","サイクル増：拘束・品質で評価")))
A20: 12 | N20: =IF(K20="","",K20-N(M20)) | O20: =IF(OR(F20="",J20=""),"",F20-J20) | P20: =IF(OR(G20="",K20=""),"",G20-K20) | Q20: =IF(OR(G20="",N20=""),"",G20-N20) | R20: =IF(OR(E20="",P20=""),"",P20*E20) | S20: =IF(OR(E20="",Q20=""),"",Q20*E20) | T20: =IF(R20="","",R20/01_前提条件!$C$9) | U20: =IF(S20="","",S20/01_前提条件!$C$9) | V20: =IF(P20="","",IF(P20>0,"サイクル短縮",IF(P20=0,"サイクル同等：拘束・品質で評価","サイクル増：拘束・品質で評価")))
... A28: 20 | N28: =IF(K28="","",K28-N(M28)) | O28: =IF(OR(F28="",J28=""),"",F28-J28) | P28: =IF(OR(G28="",K28=""),"",G28-K28) | Q28: =IF(OR(G28="",N28=""),"",G28-N28) | R28: =IF(OR(E28="",P28=""),"",P28*E28) | S28: =IF(OR(E28="",Q28=""),"",Q28*E28) | T28: =IF(R28="","",R28/01_前提条件!$C$9) | U28: =IF(S28="","",S28/01_前提条件!$C$9) | V28: =IF(P28="","",IF(P28>0,"サイクル短縮",IF(P28=0,"サイクル同等：拘束・品質で評価","サイクル増：拘束・品質で評価")))
A29: 合計（記入例を除く） | R29: =SUM(R9:R28) -> 0 | S29: =SUM(S9:S28) -> 0 | T29: =SUM(T9:T28) -> 0 | U29: =SUM(U9:U28) -> 0
A30: 対象：TNF／GW／Montbell／HH の ファスナー・ポケット・フードキルト等。大型＝70×120（130×95機）、中型＝40×60。
A32: 2. シームシーリング Spec-D：ロングアーム工程（袖・裾など長尺パーツ）の2名体制 → 1名化
A33: No | B33: 工程 | D33: 年間数量(枚) | E33: 現行 工程秒/枚 | F33: 現行 人数 | G33: Spec-D 工程秒/枚 | H33: Spec-D 人数 | I33: 現行 人秒/年 | K33: Spec-D 人秒/年 | M33: 年間削減工数(秒) | O33: 省人工数(人) | Q33: 備考
A34: 記入例 | B34: 袖 ロングアーム（例） | D34: 10000 | E34: 60 | F34: 2 | G34: 60 | H34: 1 | I34: =IF(OR(D34="",E34="",F34=""),"",E34*F34*D34) -> 1200000 | K34: =IF(OR(D34="",G34="",H34=""),"",G34*H34*D34) -> 600000 | M34: =IF(OR(I34="",K34=""),"",I34-K34) -> 600000 | O34: =IF(M34="","",M34/01_前提条件!$C$9) -> 0.070621469 | Q34: 数値はすべて仮置き（形式の例）
A35: 1 | I35: =IF(OR(D35="",E35="",F35=""),"",E35*F35*D35) | K35: =IF(OR(D35="",G35="",H35=""),"",G35*H35*D35) | M35: =IF(OR(I35="",K35=""),"",I35-K35) | O35: =IF(M35="","",M35/01_前提条件!$C$9)
A36: 2 | I36: =IF(OR(D36="",E36="",F36=""),"",E36*F36*D36) | K36: =IF(OR(D36="",G36="",H36=""),"",G36*H36*D36) | M36: =IF(OR(I36="",K36=""),"",I36-K36) | O36: =IF(M36="","",M36/01_前提条件!$C$9)
A37: 3 | I37: =IF(OR(D37="",E37="",F37=""),"",E37*F37*D37) | K37: =IF(OR(D37="",G37="",H37=""),"",G37*H37*D37) | M37: =IF(OR(I37="",K37=""),"",I37-K37) | O37: =IF(M37="","",M37/01_前提条件!$C$9)
A38: 4 | I38: =IF(OR(D38="",E38="",F38=""),"",E38*F38*D38) | K38: =IF(OR(D38="",G38="",H38=""),"",G38*H38*D38) | M38: =IF(OR(I38="",K38=""),"",I38-K38) | O38: =IF(M38="","",M38/01_前提条件!$C$9)
A39: 5 | I39: =IF(OR(D39="",E39="",F39=""),"",E39*F39*D39) | K39: =IF(OR(D39="",G39="",H39=""),"",G39*H39*D39) | M39: =IF(OR(I39="",K39=""),"",I39-K39) | O39: =IF(M39="","",M39/01_前提条件!$C$9)
A40: 6 | I40: =IF(OR(D40="",E40="",F40=""),"",E40*F40*D40) | K40: =IF(OR(D40="",G40="",H40=""),"",G40*H40*D40) | M40: =IF(OR(I40="",K40=""),"",I40-K40) | O40: =IF(M40="","",M40/01_前提条件!$C$9)
A41: 7 | I41: =IF(OR(D41="",E41="",F41=""),"",E41*F41*D41) | K41: =IF(OR(D41="",G41="",H41=""),"",G41*H41*D41) | M41: =IF(OR(I41="",K41=""),"",I41-K41) | O41: =IF(M41="","",M41/01_前提条件!$C$9)
A42: 8 | I42: =IF(OR(D42="",E42="",F42=""),"",E42*F42*D42) | K42: =IF(OR(D42="",G42="",H42=""),"",G42*H42*D42) | M42: =IF(OR(I42="",K42=""),"",I42-K42) | O42: =IF(M42="","",M42/01_前提条件!$C$9)
A43: 合計（記入例を除く） | M43: =SUM(M35:N42) -> 0 | O43: =SUM(O35:P42) -> 0
A45: 3. 集計：省人工数と再配置可能人員（拘束時間基準）
B46: 項目 | E46: 値 | I46: 備考
B47: パターンシーマ 中型（No.4）省人工数 | E47: =SUMIF(D9:D28,"中",U9:U28) -> 0 | I47: 07表1 D列＝中
B48: パターンシーマ 大型（No.5）省人工数 | E48: =SUMIF(D9:D28,"大",U9:U28) -> 0 | I48: 07表1 D列＝大
B49: Spec-D（No.7）省人工数 | E49: =O43 -> 0 | I49: 07表2
...

Sheet 08_PS運用設計
A1: パターンシーマ 運用設計（3/25要確認事項②）
A2: パターンシーマは導入することが目的にならないように、動線、人配置、縫製中の工員の動きを含めて運用設計する。
A3: 1. 原則
A4: 原則 | B4: 内容
A5: 成果指標 | B5: 台数ではなく、工程集約・作業者拘束時間削減・属人性排除・習熟期間短縮・品質安定・必要工数削減で評価する
A6: APICで自動化が効く理由 | B6: APICは多品種・切替型。同一品番を通年生産するなら人の熟練で最大効率に近づけるが、品番切替のたびに習熟がリセットされるため、熟練に依存しない自動機の優位性が大きい
A7: 1人複数台 | B7: 前提にしない。動線とサイクルの実測で、自動縫製中に他方のセット・取り出しが収まることを確認できた場合のみ採用
A8: 余力人員 | B8: 削減ではなく前後工程へ再配置（例：30人必要→28人で同じ生産量→2人を他工程へ）
A10: 2. Before／After 作業フロー
A11: ステップ | B11: 手作業（Before） | C11: 改善治具＋1本針 | D11: パターンシーマ（After） | E11: 作業者の状態
A12: ① パーツ準備 | B12: パーツを揃え、印付け | C12: パーツを揃える | D12: 型枠（テンプレート）単位でパーツを揃える | E12: 拘束
A13: ② セット | B13: 合わせ・ピン打ち | C13: 治具にセット | D13: 型枠にパーツをセット → 機械に装着 | E13: 拘束
A14: ③ 縫製 | B14: 手縫い（例：6工程） | C14: 1本針で縫製（例：3工程） | D14: 自動縫製（例：2工程） | E14: Before：拘束／After：非拘束
A15: ④ 自動縫製中 | B15: － | C15: － | D15: 2枚目の型枠に次製品をセット、前製品の糸処理・検品 | E15: 並行作業（実測対象）
A16: ⑤ 取り出し・検品 | B16: 検品 | C16: 治具から外して検品 | D16: 型枠から取り出し・検品 → 次の型枠を装着 | E16: 拘束
A18: 3. 配置案
A19: 機種 | B19: 配置 | C19: 理由 | D19: 留意点 | E19: 確認者
A20: 中型 60×40（No.4） | B20: 対象ラインのポケットファスナー工程位置にライン内配置 | C20: 機体が小さくライン内に入る（2/25確認） | D20: 型枠2枚運用で縫製中に次をセット。前後工程との仕掛り置場 | E20: ライン長・IE
A21: 大型 130×95（No.5） | B21: 複数ライン共用セル（フロントファスナー・キルティング） | C21: 品番により負荷が大きく変動 | D21: 搬送距離、仕掛り置場、ライン間の優先順位ルール | E21: 生産管理・IE
A22: 型枠（テンプレート） | B22: 品番別に製作・保管・識別 | C22: 多品種切替では型枠準備が律速になる | D22: 新品番の投入前に型枠製作リードタイムを確保（生産準備ワークフローへ組込み） | E22: 技術
A24: 4. 人配置の判断条件（1人2台にする場合）
A25: 条件 | B25: 判定方法
A26: 自動縫製秒 ≥ もう1台のセット秒＋取り出し秒＋検品秒＋移動秒 | B26: 07表1の実測値（自動縫製秒・並行作業秒）で確認
A27: 2台間の移動距離が短い（目安：数歩以内） | B27: レイアウト図で確認
A28: 待ち（機械待ち・人待ち）が発生しない | B28: 10サイクル以上のビデオ測定で確認
A30: 5. 測定計画
A31: 測定項目 | B31: 方法 | C31: 回数 | D31: 時期 | E31: 担当
A32: 工程秒（Before／After） | B32: ビデオ撮影＋ストップウォッチ | C32: 各工程10サイクル以上 | D32: 導入前・導入1か月後 | E32: IE・工程担当
A33: 作業者拘束時間・並行作業時間 | B33: 自動縫製中の作業内容を記録 | C33: 同上 | D33: 同上 | E33: IE
A34: 習熟期間 | B34: 新人が標準時間に到達するまでの日数 | C34: 対象者ごと | D34: 導入後 | E34: ライン長
A35: 不良率 | B35: 工程内不良・最終検品 | C35: 1か月集計 | D35: 導入前後 | E35: QC
A36: 稼働率 | B36: PS稼働時間÷就業時間 | C36: 週次 | D36: 導入後 | E36: 生産管理

Sheet 09_スポットプレス
A1: スポットプレス 必要台数と入替計画（No.11・最優先／安全投資）
A2: 安全装置なしの旧型は安全上の理由で全数入替。ROIで判断しない。必要総数＝対象ライン数×必要台数/ライン＋共用分＋予備・保全分。
A3: A. 現有機の状況
A4: 区分 | B4: 台数 | C4: 年式・使用年数 | D4: 安全装置 | E4: 後付け可否 | F4: 修理可否 | G4: 備考
A5: 旧型（アーム斜め動作） | C5: 約15年 | D5: 無 | E5: 不可（メーカー確認、廃棄推奨） | G5: 圧力計算不可・3L等に使用不可。圧力ムラで再プレス増
A6: 新型 PTTG 30×10cm | B6: 15 | D6: 有 | E6: － | F6: － | G6: 原案S14・R14
A8: B. 必要台数の計算
A9: 項目 | C9: 値 | E9: 備考
A10: 対象ライン数 | E10: スポットプレスを使う量産ライン数
A11: 1ライン当たり必要台数 | E11: ライン別使用状況（C表）から設定
A12: ライン計 | C12: =IF(OR(C10="",C11=""),"",C10*C11)
A13: 共用分（仕上げ・サンプル・部分プレス等）
A14: 予備・保全分 | E14: 故障・修理中の代替
A15: 計算上の必要総数 | C15: =IF(C12="","",ROUNDUP(C12+N(C13)+N(C14),0))
A16: 暫定 必要総数（3/25概算45〜50台の下限） | C16: 45 | E16: 計算根拠の入力が終わるまでの暫定値
A17: 採用 必要総数 | C17: =IF(C15="",C16,C15) -> 45 | E17: =IF(C15="","※暫定値を使用中：上の計算欄を入力すると自動で置き換わる","計算値を使用") -> ※暫定値を使用中：上の計算欄を入力すると自動で置き換わる
A18: 新型（安全装置付）現有 | C18: =B6 -> 15
A19: 原案① 計上台数 | C19: 10
A20: 2026年度 購入必要数 | C20: =MAX(0,C17-C18) -> 30 | E20: → 02_投資総括 No.11 の調整案台数
A21: うち 更新分（旧型の置換） | C21: =IF(B5="","旧型台数入力待ち",MIN(C20,B5)) -> 旧型台数入力待ち
A22: うち 純増分 | C22: =IF(B5="","旧型台数入力待ち",C20-C21) -> 旧型台数入力待ち
A23: 原案との差（台） | C23: =C20-C19 -> 20
A24: 単価（USD） | C24: =02_投資総括!$F$15 -> 764 | E24: 02_投資総括
A25: 購入金額（USD） | C25: =C20*C24 -> 22920
A26: 購入金額（円） | C26: =C25*01_前提条件!$C$5 -> 3667200
A27: 購入後の旧型（安全装置なし） | C27: 全数使用停止・廃棄 | E27: 必要総数をすべて安全装置付で充足
A29: C. ライン別 使用状況（現況調査）
A30: ライン・工程 | B30: 旧型 使用台数 | C30: 新型 使用台数 | D30: ピーク時 必要台数 | E30: 主な用途 | G30: 備考
A43: 合計 | B43: =SUM(B31:B42) -> 0 | C43: =SUM(C31:C42) -> 0 | D43: =SUM(D31:D42) -> 0
A45: D. 証跡チェックリスト
A46: 証跡 | B46: 内容 | C46: 状態
A47: 旧型の写真 | B47: 安全装置がないことが分かる写真（挟まれ箇所）
A48: メーカー見解 | B48: 安全装置の後付け不可・廃棄推奨の書面またはメール
A49: 年式・台帳 | B49: 固定資産台帳の取得年・簿価
A50: 故障・修理履歴 | B50: 修理可否、部品入手可否
A51: ヒヤリハット | B51: 挟まれ・やけど等の記録（あれば）
A52: 品質影響 | B52: 圧力ムラによる再プレス回数、耐水圧不良との関係
A54: E. 説明文案
A55: 旧型スポットプレスは約15年経過し、安全装置の後付けができずメーカーも廃棄を推奨している。安全上の問題があるため、費用対効果ではなく安全確保を理由に最優先で全数入替を行う。必要総数は［対象ライン数×必要台数/ライン＋共用分＋予備分］で算出し、安全装置付の新型現有15台との差を2026年度に購入する。

Sheet 10_平プレス検証
A1: No.10 平プレス（125×83cm） プレス精度の検証方法（3/25要確認事項⑤）
A2: 大型だからこそ圧力・温度の均一性が懸念にならないよう、受入時と定期で確認する。判定基準の数値はメーカー（H&H／JUKI）規格を取得して記入。
A3: 検証項目 | B3: 検証方法 | C3: 判定基準 | D3: 確認頻度 | E3: 担当
A4: 水平度 | B4: 水平器で熱板の4隅を測定（必要に応じ中央を追加） | C4: 4点とも許容範囲内（許容値：メーカー規格） | D4: 受入時・月次・移設/修理後 | E4: 保全
A5: 圧着均一性 | B5: 紙挟みテスト：熱板全面に紙片を配置（例：3×3＝9点）してプレスし、圧痕・引抜き抵抗の均一性を確認 | C5: 全点で圧痕が均一、抜け・弱い点がない | D5: 受入時・週次・品番切替時 | E5: 技術
A6: 圧力分布（補足） | B6: 感圧紙（圧力測定フィルム）で熱板全面の圧力分布を可視化 | C6: 発色ムラが許容範囲内 | D6: 受入時・年次・異常時 | E6: 技術／メーカー
A7: 温度 | B7: 接触式表面温度計で熱板9点を測定 | C7: 設定温度±許容差内（メーカー規格） | D7: 始業時（中央1点）・月次（9点） | E7: 工程リーダー／保全
A8: 圧力 | B8: 圧力計の表示と設定値を照合 | C8: 設定値±許容差内（メーカー規格） | D8: 始業時 | E8: 工程リーダー
A9: 接着品質 | B9: 実素材（PUR接着・TNFエアチャンバー）のテストピースで剥離強度・耐水圧・外観を確認 | C9: 顧客／社内規格を満たす | D9: 受入時・新品番立上げ時 | E9: 品質
A10: メーカー校正・保守 | B10: メーカーによる温度・圧力のキャリブレーションと定期保守 | C10: 校正記録を保管 | D10: 年1回（頻度はメーカー推奨を確認） | E10: 保全／メーカー
A12: 記録：検証結果は日付・測定値・判定・担当を記録表に残し、異常時はプレス停止→保全連絡→再検証の手順とする。

Sheet 11_縮絨試験
A1: 縮絨機 検討ステップ（3/25要確認事項⑦）
A2: 結論：2026年度予算には計上しない。QN事例確認と小規模試験の結果で導入／見送りを判断する（試験後に導入判断）。
A3: No | B3: ステップ | C3: 内容 | D3: 判断基準 | E3: 担当 | F3: 状態
A4: 1 | B4: QN事例確認 | C4: QNで使用している生地、条件（温度・時間・張力）、改善した品質項目 | D4: 事例と効果データがあるか | E4: TIVN・加技部
A5: 2 | B5: 対象生地の選定 | C5: APICで寸法・風合いが不安定な生地（サプライヤー別） | D5: 不良・クレーム実績 | E5: APIC品質
A6: 3 | B6: 使用条件 | C6: どの工程で使うか（裁断前の生地安定化など） | D6: 工程・LTへの影響 | E6: APIC技術
A7: 4 | B7: 品質改善効果 | C7: 寸法変化率・斜行・外観の Before／After | D7: 改善幅が規格内に収まるか | E7: APIC品質
A8: 5 | B8: APIC適用性 | C8: 設置スペース、処理能力、リードタイム影響、外注の可否 | D8: 内製の必要性 | E8: APIC生産管理
A9: 6 | B9: 小規模試験 | C9: QNまたは外部で小ロット試験 | D9: 4の基準を満たすか | E9: TIVN
A10: 7 | B10: 導入／見送り判断 | C10: 効果が数値で確認できた場合のみ次年度以降に予算化 | D10: － | E10: TIVN・TIJ
A12: 経緯：過去にAPICでウールの縮絨テストを実施したが効果は明確でなかった。生地が不安定なサプライヤーが多く、工場側で生地を安定させる手段として検討。

Sheet 12_レンタル費
A1: 外部レンタル費と投資による回避可能額（3/25要確認事項①）
A2: 投資でレンタルが全てなくなるわけではない。回避率（G列）を機種別に設定し、回避可能な部分のみを効果として計上する。
B3: 2025年 レンタル費 総額（USD） | D3: 4890.75 | F3: 出所：APIC_2025年 機械レンタル費用総額.xlsx
A5: 年 | B5: 区分・機種 | C5: 台数 | D5: 期間 | E5: 金額(USD) | F5: 対応投資キー | G5: 回避率 | H5: 回避可能額(USD) | I5: 出所・備考
A6: 2025 | B6: 大型パターンシーマ | E6: 3016.54 | F6: PS大 | G6: 1 | H6: =IF(OR(E6="",G6=""),"",E6*G6) -> 3016.54 | I6: 回避率100%は『No.5購入台数で繁忙期需要を賄える』前提（仮）。レンタル台数・期間を確認
A7: 2025 | B7: その他機種（内訳未確認） | E7: =D3-E6 -> 1874.21 | G7: 0 | H7: =IF(OR(E7="",G7=""),"",E7*G7) -> 0 | I7: 内訳確認後に機種別へ分割。原案No.6の13,440USD/年はこの金額（最大1,874.21USD）と整合しない
A8: 2024 | B8: ロックミシン（10〜12月、約10台） | C8: 10 | D8: 3か月 | F8: ロック | H8: =IF(OR(E8="",G8=""),"",E8*G8) | I8: 金額はD/Nから入力。回避率は購入後も残る不足（05）を考慮して設定
A9: 2024 | B9: その他 | H9: =IF(OR(E9="",G9=""),"",E9*G9)
A10: 2026 | B10: 実績（年初〜） | H10: =IF(OR(E10="",G10=""),"",E10*G10)
H11: =IF(OR(E11="",G11=""),"",E11*G11)
H12: =IF(OR(E12="",G12=""),"",E12*G12)
H13: =IF(OR(E13="",G13=""),"",E13*G13)
H14: =IF(OR(E14="",G14=""),"",E14*G14)
A15: 合計 | E15: =SUM(E6:E14) -> 4890.75 | H15: =SUM(H6:H14) -> 3016.54 | I15: 年度が混在（直近実績ベース）。同一機種の重複計上に注意
A16: 対応投資キー：ロック／PS大／PS中／DUMA／SpecD／温冷／平プレス（13_費用対効果PLが同じキーで集計）。
A18: 明細（D/N・Invoice単位）
A19: 年月 | B19: D/N・Invoice No. | C19: 台数 | D19: 期間(日) | E19: 金額(USD) | F19: 機種・型式 | G19: style | H19: line | I19: 回避可否・理由
A45: 合計 | E45: =SUM(E20:E44) -> 0

Sheet 13_費用対効果PL
A1: 費用対効果（改善投資）と当年度P/L影響
A2: 年間純効果＝レンタル削減＋外注費削減＋省人効果＋品質効果＋電力削減−追加保守・消耗品 ／ 単純回収年数＝投資額÷年間純効果
A4: 投資案件 | B4: 原案No. | C4: 投資額(USD) | D4: レンタル削減 | E4: 外注費削減 | F4: 省人工数(人) | G4: 省人効果 | H4: 品質効果 | I4: 電力削減 | J4: 追加保守・消耗品 | K4: 年間純効果(USD/年) | L4: 単純回収年数 | M4: 評価・備考
A5: ロックミシン OL＋IL | B5: 1,2 | C5: =02_投資総括!$J$5+02_投資総括!$J$6 -> 7200 | D5: =SUMIF(12_レンタル費!$F$6:$F$14,"ロック",12_レンタル費!$H$6:$H$14) -> 0 | G5: =IF(OR(01_前提条件!$C$14="",F5=""),0,F5*01_前提条件!$C$14) -> 0 | I5: =06_サーボ電力!$B$21 -> 262.9984 | K5: =N(D5)+N(E5)+N(G5)+N(H5)+N(I5)-N(J5) -> 262.9984 | L5: =IF(D5=0,"レンタル実績額 入力待ち",C5/K5) -> レンタル実績額 入力待ち | M5: 主目的は不足解消（生産継続）。電力は副次効果
A6: パターンシーマ 中型 | B6: 4 | C6: =02_投資総括!$J$8 -> 13350 | D6: =SUMIF(12_レンタル費!$F$6:$F$14,"PS中",12_レンタル費!$H$6:$H$14) -> 0 | F6: =07_省人効果!$E$47 -> 0 | G6: =IF(01_前提条件!$C$14="",0,F6*01_前提条件!$C$14) -> 0 | K6: =N(D6)+N(E6)+N(G6)+N(H6)+N(I6)-N(J6) -> 0 | L6: =IF(K6>0,C6/K6,"効果データ待ち") -> 効果データ待ち | M6: 省人は07の実測入力後に確定
A7: パターンシーマ 大型 | B7: 5 | C7: =02_投資総括!$J$9 -> 26000 | D7: =SUMIF(12_レンタル費!$F$6:$F$14,"PS大",12_レンタル費!$H$6:$H$14) -> 3016.54 | E7: 3000 | F7: =07_省人効果!$E$48 -> 0 | G7: =IF(01_前提条件!$C$14="",0,F7*01_前提条件!$C$14) -> 0 | K7: =N(D7)+N(E7)+N(G7)+N(H7)+N(I7)-N(J7) -> 6016.54 | L7: =IF(K7>0,C7/K7,"効果データ待ち") -> 4.3214206 | M7: 外注費3,000USD＝25FWキルティング外注（原案R8）。年間額（SS＋FW）を確認
A8: 本縫針送りミシン DUMA | B8: 6 | C8: =02_投資総括!$J$10 -> 8800 | D8: =SUMIF(12_レンタル費!$F$6:$F$14,"DUMA",12_レンタル費!$H$6:$H$14) -> 0 | G8: =IF(OR(01_前提条件!$C$14="",F8=""),0,F8*01_前提条件!$C$14) -> 0 | K8: =N(D8)+N(E8)+N(G8)+N(H8)+N(I8)-N(J8) -> 0 | L8: =IF(K8>0,C8/K8,"効果データ待ち") -> 効果データ待ち | M8: レンタル削減は2025明細で確認（原案の13,440USD/年は不整合）
A9: シームシーリング Spec-D | B9: 7 | C9: =02_投資総括!$J$11 -> 19400 | D9: =SUMIF(12_レンタル費!$F$6:$F$14,"SpecD",12_レンタル費!$H$6:$H$14) -> 0 | F9: =07_省人効果!$E$49 -> 0 | G9: =IF(01_前提条件!$C$14="",0,F9*01_前提条件!$C$14) -> 0 | K9: =N(D9)+N(E9)+N(G9)+N(H9)+N(I9)-N(J9) -> 0 | L9: =IF(K9>0,C9/K9,"効果データ待ち") -> 効果データ待ち | M9: 2名体制→1名化の効果
A10: 温冷プレス 60×12 | B10: 9 | C10: =02_投資総括!$J$13 -> 24900 | D10: =SUMIF(12_レンタル費!$F$6:$F$14,"温冷",12_レンタル費!$H$6:$H$14) -> 0 | G10: =IF(OR(01_前提条件!$C$14="",F10=""),0,F10*01_前提条件!$C$14) -> 0 | K10: =N(D10)+N(E10)+N(G10)+N(H10)+N(I10)-N(J10) -> 0 | L10: =IF(K10>0,C10/K10,"効果データ待ち") -> 効果データ待ち | M10: 工程秒約半減（原案）→ 削減秒×数量で省人を算出し入力
A11: 平プレス 125×83 | B11: 10 | C11: =02_投資総括!$J$14 -> 13000 | D11: =SUMIF(12_レンタル費!$F$6:$F$14,"平プレス",12_レンタル費!$H$6:$H$14) -> 0 | G11: =IF(OR(01_前提条件!$C$14="",F11=""),0,F11*01_前提条件!$C$14) -> 0 | K11: =N(D11)+N(E11)+N(G11)+N(H11)+N(I11)-N(J11) -> 0 | L11: =IF(K11>0,C11/K11,"効果データ待ち") -> 効果データ待ち | M11: プレス回数削減を品番別に計測
A12: 改善投資 合計 | C12: =SUM(C5:C11) -> 112650 | D12: =SUM(D5:D11) -> 3016.54 | E12: =SUM(E5:E11) -> 3000 | F12: =SUM(F5:F11) -> 0 | G12: =SUM(G5:G11) -> 0 | H12: =SUM(H5:H11) -> 0 | I12: =SUM(I5:I11) -> 262.9984 | J12: =SUM(J5:J11) -> 0 | K12: =SUM(K5:K11) -> 6279.5384 | L12: =IF(COUNTIF(L5:L11,"*待ち")>0,"一部データ待ち",C12/K12) -> 一部データ待ち
A13: 省人効果（G列）は前提条件C14（人件費）入力後に金額化。省人は再配置であり、人件費の削減ではなく『追加採用の回避・生産量増』として説明する。
A15: ROI対象外（安全・顧客要求・検証）
A16: 投資案件 | B16: 原案No. | C16: 投資額(USD) | D16: 判断理由
A17: スポットプレス | B17: 11 | C17: =02_投資総括!$J$15 -> 22920 | D17: 安全（安全装置なし旧型の全数入替）。金額換算しない
A18: Nawon温冷プレス 4種 | B18: 12-15 | C18: =02_投資総括!$J$16+02_投資総括!$J$17+02_投資総括!$J$18+02_投資総括!$J$19 -> 98253 | D18: 顧客要求（26FW GW要請）。受注維持
A19: Spec-IJ・US-512 | B19: 8,18 | C19: =02_投資総括!$J$12+02_投資総括!$J$22 -> 13100 | D19: 戦略／検証（少数導入して評価）
A21: 当年度P/L影響（年額・円）
A22: 当年度P/L影響＝新規設備年間償却−既存設備償却減少額−年間削減効果 （＋＝費用増 → 安全・顧客要求・生産継続の必要性で説明／−＝P/L改善）
A23: 項目 | C23: ケースA | D23: ケースB | F23: 備考
A24: 調整案 投資総額（USD） | C24: =02_投資総括!$J$26 -> 246923 | D24: =02_投資総括!$J$26 -> 246923 | F24: 02_投資総括
A25: うちTI償却対象（USD） | C25: =C24 -> 246923 | D25: =C24-01_前提条件!$C$12 -> 196923 | F25: A：APIC負担分もTI資産として償却（保守的）／B：APIC負担50,000USDをTI償却対象から除外。資産保有者・償却処理を確認するまでAを基本とする
A26: 新規設備 年間償却（円） | C26: =C25*01_前提条件!$C$5/01_前提条件!$C$11 -> 5643954.3 | D26: =D25*01_前提条件!$C$5/01_前提条件!$C$11 -> 4501097.1 | F26: 定額・償却年数は前提条件
A27: 既存設備 償却減少額（円） | D27: =C27 -> 0 | F27: 入替で除却する既存機の年間償却。ロック旧機・旧型スポットプレスは償却済が多い（例：原案V4＝W4）→ 0なら空欄
A28: 年間削減効果（円） | C28: =K12*01_前提条件!$C$5 -> 1004726.1 | D28: =C28 -> 1004726.1 | F28: 改善投資の年間純効果（上表）
A29: 当年度P/L影響（円） | C29: =C26-N(C27)-C28 -> 4639228.1 | D29: =D26-N(D27)-D28 -> 3496371
A30: 判定 | C30: =IF(C29>0,"費用増：安全・顧客要求・生産継続で説明","P/L改善") -> 費用増：安全・顧客要求・生産継続で説明 | D30: =IF(D29>0,"費用増：安全・顧客要求・生産継続で説明","P/L改善") -> 費用増：安全・顧客要求・生産継続で説明

Sheet 14_原案チェック
A1: 原案（20260403版）の整合性チェック ― 提出前の修正候補
A2: TIJから指摘される前に修正しておくべき箇所。原案ファイル『2026年度 設備投資案』シートのセル番地で記載。
A3: No | B3: 箇所 | C3: 内容 | D3: 影響 | E3: 対応案
A4: 1 | B4: R9（No.6 DUMA） | C4: 年間レンタル費削減額 112USD×12か月×10台＝13,440USD/年、回収0.7年と記載 | D4: 2025年のレンタル費総額は4,890.75USD（大型PSを除くと1,874.21USD）で、記載の削減額は実績と整合しない。数値根拠の信頼性が問われる | E4: 2025明細の針送りミシン分に置き換える。または『レンタル単価112USD/月・台』を前提とした想定値と明記する
A5: 2 | B5: R4（No.1） | C5: 『1ラインあたり平均4台稼働』と記載 | D5: 31ライン×4台＝124台となり必要台数が過大に見える | E5: 製品構成（80%×3台＋20%×4台）＝平均3.2台、通常100台／ピーク112台に統一（05）
A6: 3 | B6: R4・S4（No.1） | C6: 『C判定機種が4台』 | D6: 新ロジック（老朽化重大故障4台・修理復旧不可・実稼働対象外）と表現が異なる | E6: 『修理復旧不可4台』に統一
A7: 4 | B7: R5・S5（No.2） | C7: R5『現状67台が稼働』、S5『68台』 | D7: 数値不一致 | E7: 現有68台（うちサンプル固定4台、生産用64台）に統一
A8: 5 | B8: I25・J25・O25 | C8: 合計式が =SUM(I12:I24) 等で4〜11行目を含まない | D8: 優先②の台数が10台（実際38台）、②金額が258,730USD（実際355,230USD）と過小表示 | E8: 合計式を SUM(I4:I24) 等に修正
A9: 6 | B9: M27 | C9: SUM式の参照先が削除されている（参照切れ） | D9: エラー値が表示される | E9: 削除または参照を修正
A10: 7 | B10: A21・A22 | C10: No.18が2行重複 | D10: 以降の番号がずれる | E10: 連番を振り直す
A11: 8 | B11: N6・N16・N19・N22〜N24 | C11: 優先①金額（N列）の式が優先②台数（I列）×L列を参照 | D11: 現在は0表示で実害はないが式が不統一 | E11: N列の式を『H列×L列』に統一
A12: 9 | B12: X18 | C12: 残存簿価が『-』（V18・W18は入力済） | D12: 簿価が表示されない | E12: X18をV18−W18の式に修正
A13: 10 | B13: O26・P26・P30 | C13: 為替150円と160円が混在 | D13: 資料により円換算額が異なる | E13: 1レートに統一（本資料は160円）
A14: 11 | B14: R8（No.5） | C14: キルティング外注『25FWで約3千USD』 | D14: 年間額か季節額か不明 | E14: SS＋FWの年間額を確認
A15: 12 | B15: 議事メモシート | C15: 発言者の個人名を含む発言録が同じブックにある | D15: 公式報告書に個人名を記載しない方針 | E15: 提出版から議事メモシートを外すか、発言者名を削除
A16: 13 | B16: 3.27確認事項シート | C16: 日付が2025/3/27（前年度の説明会資料） | D16: 2026年度資料と混同される | E16: 提出版から外す

Sheet 03_要確認事項
A1: 要確認事項への回答（3/25打合せ ①〜⑦＋新規条件）
A2: 現状 → 課題 → 数値根拠 → 導入効果 → 費用対効果 → 投資妥当性 → 優先順位 の順に説明する。
A3: No | B3: 確認事項 | C3: 回答骨子 | D3: 数値・根拠 | E3: 根拠シート | F3: 未確定データ・次アクション | G3: 状態
A4: ① | B4: 機材導入で削減できる年間外部レンタル費。パターンシーマ・Spec-D導入による要員減の数値 | C4: レンタル費は機種別に『投資で回避できる部分』だけを効果計上（100%計上しない）。省人化は人員削減ではなく『工程秒削減→必要工数削減→必要人員減→余力人員の再配置→工場全体の生産性向上』と定義し、Before/After実測で算出。 | D4: 2025年レンタル総額4,890.75USD（うち大型PS 3,016.54USD）。省人工数＝年間削減工数÷1人年間有効稼働秒（8h×295日）。 | E4: 12_レンタル費 07_省人効果 13_費用対効果PL | F4: 2024・2026年レンタル明細（機種・台数・期間・D/N・style/line）、PS・Spec-Dの実測（工程秒・拘束秒）、対象品番の年間数量 | G4: 枠組み完成・データ入力待ち
A5: ② | B5: パターンシーマ導入時の動線・工員配置・縫製中の動きの設計 | C5: 導入を目的化しない。中型はライン内配置、大型は共用セル。自動縫製中に次製品をセットする型枠2枚運用を前提とし、1人複数台は実測で並行作業時間を確認できた場合のみ採用。 | D5: Before/Afterフロー（作業者→セット→自動縫製→縫製中に次製品準備→取り出し）と測定計画（各工程10サイクル以上） | E5: 08_PS運用設計 | F5: 現場レイアウト図、型枠製作体制、実測結果 | G5: 運用案作成済・現場検証待ち
A6: ③ | B6: スポットプレスを最優先で入替。必要台数の計算根拠と現在の運用状況 | C6: 安全装置なしの旧型（約15年、後付け不可・メーカー廃棄推奨）は安全上の理由で全数入替。必要総数＝対象ライン数×必要台数/ライン＋共用分＋予備・保全分。ROIではなく安全で判断。更新分と純増分を分けて表示。 | D6: ="暫定：必要"&TEXT(09_スポットプレス!$C$17,"0")&"台−新型現有"&TEXT(09_スポットプレス!$C$18,"0")&"台＝購入"&TEXT(09_スポットプレス!$C$20,"0")&"台（原案10台）" -> 暫定：必要45台−新型現有15台＝購入30台（原案10台） | E6: 09_スポットプレス | F6: 旧型台数・年式・修理可否、ライン別使用台数、ピーク需要、写真・ヒヤリハット | G6: 計算式完成・現況データ待ち
A7: ④ | B7: ダウン充填機の優先度を下げる | C7: 2026年度は購入見送り（現有4台で最大10ライン対応可） | D7: － | E7: 02_投資総括 | F7: － | G7: 対応済
A8: ⑤ | B8: No.10平プレスのプレス精度の検証方法 | C8: 水平器4点測定、紙挟みテスト（＋感圧紙）、温度・圧力の実測、実素材での接着評価、メーカー校正を組み合わせ、受入時と定期で確認。 | D8: 検証項目｜検証方法｜判定基準｜確認頻度｜担当 の表で定義 | E8: 10_平プレス検証 | F8: 判定基準のメーカー規格値、校正周期 | G8: 案作成済・メーカー確認待ち
A9: ⑥ | B9: 定常投資とは別に48百万円枠を利用できるか | C9: 本資料の対象外（TIJ側の確認事項）。本案は定常投資枠内・4,000万円以下で構成。 | D9: － | E9: － | F9: － | G9: TIJ確認
A10: ⑦ | B10: 縮絨機の導入検討（QN事例を含め確認） | C10: 2026年度は購入せず、QN事例確認→対象生地→使用条件→品質改善効果→APIC適用性→小規模試験→導入／見送り判断。 | D10: APIC過去試験（ウール）は効果が明確でなかった | E10: 11_縮絨試験 | F10: QN事例（生地・条件・効果） | G10: 試験計画作成済
A11: 新 | B11: APICが投資額のうち50,000USDを負担 | C11: 負担対象の機種・資産保有者・償却処理を確認するまで、TI償却の減少として自動計上しない（P/LはケースA/Bを併記）。 | D11: ="TI負担＝調整案"&TEXT(02_投資総括!$J$26,"#,##0")&"USD−50,000USD" -> TI負担＝調整案246,923USD−50,000USD | E11: 02_投資総括 13_費用対効果PL | F11: 負担対象機種、資産保有者、償却処理 | G11: 要確認
A12: 新 | B12: 投資額はSuntoolを除き概ね4,000万円以下 | C12: 安全・顧客要求・生産継続を確保し、改善投資は段階導入（効果確認後に追加）として調整。 | D12: ="調整案 "&TEXT(02_投資総括!$K$26/1000000,"0.00")&"百万円（原案① "&TEXT(02_投資総括!$H$26*01_前提条件!$C$5/1000000,"0.00")&"百万円）" -> 調整案 39.51百万円（原案① 42.77百万円） | E12: 02_投資総括 | F12: 為替レートの統一（150円／160円） | G12: 調整案作成済

Sheet 04_機種別比較
A1: 機種別比較（現状方式｜改善・代替案｜新設備案｜差分｜年間効果｜投資判断）
A2: ダウン充填装置比較の形式を踏襲。購入以外の代替案を必ず比較し、効果は数値で確認できるものだけを記載。
A3: 優先 | B3: 原案No. | C3: 設備 | D3: 投資区分 | E3: 現状方式 | F3: 改善・代替案（購入以外） | G3: 新設備案 | H3: 差分 | I3: 年間効果（数値） | J3: 投資判断（調整案） | K3: 根拠シート
A4: 1 | B4: 11 | C4: スポットプレス | D4: 必須（安全） | E4: 旧型：約15年経過、アームが斜め動作で圧力計算不可、安全装置なし。3L等の厳しい条件に使えず、圧力ムラで再プレス増。新型30×10cm 15台保有 | F4: 安全装置の後付け：不可（メーカー確認、廃棄推奨）／修理継続：安全リスクが残る | G4: PTTG 30×10cm（安全装置付）764USD/台 | H4: 安全装置あり、垂直加圧で圧力管理可、3L対応 | I4: 安全リスク解消（金額換算しない）。再プレス回数は導入後に計測 | J4: 最優先。台数＝09の計算（暫定30台） | K4: 09_スポットプレス
A5: 2 | B5: 12-15 | C5: Nawon温冷プレス 4種 | D5: 必須（顧客要求） | E5: 現状のシーム機だけでは対応できない品番あり（26FW GW要請、SW1課から4種の導入要望）。2025年度にHTM-8601を1台導入済 | F5: H&H同等機：CSL-206 9,500／CSL-213 14,500／CSL-207 10,500USD。カーブ部はNawonがアーム調整の自由度で優位、ストレート型は性能差が小さい | G5: Nawon HTM-8749×2、8739×1、8709×1、8601×1 | H5: フロントジッパー・袖・裾・フード曲線を一度で均一にプレス | I5: 顧客要求への対応（受注維持）。品番別不良率を導入後に確認 | J5: 5台。HTM-8709はH&H代替で▲9,480USDの余地（営業確認要） | K5: 02_投資総括
A6: 3 | B6: 1・2 | C6: ロックミシン OL／IL | D6: 必須（生産継続） | E6: OL実稼働86台（現有102−故障4−サンプル12）に対しピーク112台→不足26台。IL実稼働64台、ピーク70台→不足6台。繁忙期は第2工場から10〜12台借用、2024年10〜12月は外部レンタル約10台 | F6: 第2工場借用の継続：先方の受注増で困難／外部レンタル：都度D/N請求／故障4台：修理復旧不可 | G6: Juki MO-6814・MO-6816（サーボ・自動糸切り） | H6: 不足解消。ペダルOFFで即停止→曲線部の縫いズレ低減。電力1台▲469.64kWh/年 | I6: 外部レンタル回避（2024実績額を入力）＋電力37.57USD/台/年（副次） | J6: OL5台（更新4＋純増1）・IL2台 | K6: 05_ロック必要台数 06_サーボ電力
A7: 4 | B7: 4 | C7: パターンシーマ 中型 60×40 | D7: 改善 | E7: 手作業6工程・340秒、改善治具＋1本針3工程・330秒（例）。熟練者依存、習熟期間が長い。GW系はポケットファスナーをPSで縫う指示あり | F7: 改善治具：工程は集約できるが作業者は全時間拘束、熟練依存が残る | G7: Hikari HMS-6040（既存5台、稼働問題なし） | H7: 2工程・310秒（例）。自動縫製中は次製品を準備でき拘束時間が減る。全ケースでサイクルが短くなるわけではない | I7: 省人工数（07で実測値から算出）、習熟期間短縮、品質安定 | J7: 3台。運用設計（08）とセットで導入 | K7: 07_省人効果 08_PS運用設計
A8: 5 | B8: 5 | C8: パターンシーマ 大型 130×95 | D8: 改善 | E8: 現有3台。2025年大型PSレンタル3,016.54USD。キルティングは外注（25FWで約3千USD、納期約1か月）。GW系はフロントファスナーをPSで縫う指示あり | F8: レンタル継続・キルティング外注継続 | G8: Hikari HMS-13095A/RND（360度回転ヘッド） | H8: レンタル・外注を内製化、納期約1か月短縮、フロントファスナーの直線性向上 | I8: レンタル3,016.54＋外注約3,000＝約6,000USD/年＋省人効果 | J8: 6→4台（段階導入、効果確認後に追加） | K8: 07_省人効果 12_レンタル費
A9: 6 | B9: 6 | C9: 本縫針送りミシン | D9: 必須（生産継続） | E9: 現有17台（DUMA8・JUKI9）、各ライン1台必要（31台）。25年度の積み残し分をレンタルで対応 | F9: Juki DDL-9010（3,500USD/台） | G9: DUMA DM1968L-NF 880USD/台 | H9: 価格は約1/4。部品はメーカー専用品（互換なし）。使用実績1年 | I9: レンタル回避額は2025明細で確認（原案13,440USD/年は不整合→修正） | J9: 10台 | K9: 12_レンタル費 14_原案チェック
A10: 7 | B10: 9 | C10: 温冷プレス 60×12 | D10: 必須（生産継続） | E10: 30×10cm 26台で不足。面積が小さくプレス回数が増えシワのリスク | F10: 現有機でプレス回数を増やす | G10: H&H CSL-201 60×12cm | H10: 1回の処理面積が約2.4倍、工程秒約半分（原案） | I10: 削減秒×対象数量で算出（数量入力待ち） | J10: 6台 | K10: 13_費用対効果PL
A11: 8 | B11: 7 | C11: シームシーリング Spec-D | D11: 改善 | E11: 袖・裾など長尺パーツは限られた熟練者または2名体制で作業 | F11: 既存機へのアタッチメント：不可（H&H・工場技術で確認済） | G11: H&H AI-002 spec-D | H11: 長尺パーツを1名で作業、テープ接着精度向上 | I11: 2名→1名分の工数削減（07で算出） | J11: 3→2台（効果確認後に追加） | K11: 07_省人効果
A12: 9 | B12: 10 | C12: 平プレス 125×83 | D12: 改善 | E12: 小型機で分割プレス→接着ムラ・シワ（TNFエアチャンバーPUR接着） | F12: 分割プレスを継続 | G12: H&H CS-691 125×83cm | H12: 大型パーツを1回でプレス | I12: プレス回数削減（品番別に計測）。精度は10の方法で担保 | J12: 2→1台（検証後に追加） | K12: 10_平プレス検証
A13: 10 | B13: 8 | C13: シームシーリング Spec-IJ | D13: 戦略／検証 | E13: フード等の曲線部でシーム剥離 | F13: － | G13: H&H AI-129 spec-IJ | H13: 傾斜ポール切替・特殊ローラー | I13: 剥離不良率で評価 | J13: 1台（評価用） | K13: －
A14: 11 | B14: 18 | C14: 超音波溶着機 US-512 | D14: 戦略／検証 | E14: 28Hz機では一部素材で溶着不良 | F14: － | G14: H&H US-512（35Hz） | H14: 薄手素材に対応 | I14: サンプル試作で評価、営業提案の幅を広げる | J14: 1台（トライアル） | K14: －
A15: 12 | B15: － | C15: 縮絨機 | D15: 戦略／検証 | E15: 生地が不安定なサプライヤーあり。過去のウール試験は効果が明確でなかった | F15: － | G15: 未定 | H15: － | I15: 試験後に判断 | J15: 2026年度は計上しない | K15: 11_縮絨試験
A16: － | B16: 3,16,17, 18※,19,20 | C16: 眠り穴・自動延反機・ダウン充填機・Nawonテーピング2機種・刺繍機 | D16: 見送り | E16: － | F16: － | G16: － | H16: － | I16: － | J16: 2026年度は計上しない（打合せ結論・原案優先②） | K16: 02_投資総括
