Workbook

Sheet 通関業者向けレター
I1: 45257
A2: 関係者 ご各位様
I3: 東レインターナショナル㈱ アパレル物流課
A5: 【ご依頼】APIC、BTNB生産の輸入におけるTIVNの業務委託費用の評価加算について
A7: 逆委託加工における手数料の法改正遵守が強化されていく中で、弊方でも、表題を中心に、
A8: あるべき姿を神戸税関や関係者と協議してきました。TIベトナムの100項目に細分化された業務内容を
A9: 1項目ずつ検討した結果、6項目が評価加算を要する課税対象とすべき内容と判断されたたため、
A10: 12月より評価加算を開始いたします。つきましては、下記詳細をご確認、ご対応願います。
A13: （１）評価加算すべき委託業務 6/100 項目 （神戸税関 包括評価申請にて以下項目について了承済み）
A22: （２）評価加算すべき額（2023年度）
A23: APIC： | B23: ='参考_APIC(2023年度) '!AV113*1000 -> 22915.059 | C23: /年 | D23: =B23/500000 -> 0.045830118 | E23: /50万着/年≒$0.05/着★
A24: BTNB： | B24: ='参考_BTNB(2023年度) '!AT114*1000 -> 6243.8232 | C24: /年 | D24: =B24/450000 -> 0.013875163 | E24: /45万着/年≒$0.02/着★
A26: （３）加算エビデンス について
A27: ベトナム側より弊各営業担当に、評価加算用エビデンスがインボイスと一緒に届くこととなります。
A28: 当該書面を各担当から御社にお渡しするように伝えております。
A29: 管理上の都合で、申告額への加算ではなく、評価加算にて対応願います。
A31: （４）開始時期
A32: 2023年度は11月の相当費用を2023年12月の出荷分より評価加算が必要。
A33: 来年5月より2024年度分の新価格にて評価加算をしていくこととなる。
A34: (以前のものに関しては今年の事後調査で修正）
A36: ≪問合せ先：東レインターナショナル㈱ アパレル物流課 田中（TEL:080-1529-8014）≫
I38: 以 上

Sheet 営業部向けレター
I1: 45257
A2: アパレル製品第2部 各位
I3: アパレル物流課
A5: 【ご依頼】APIC、BTNB生産の輸入におけるTIVNの業務委託費用の評価加算について
A7: 税関にて、逆委託加工における手数料の評価加算への考え方が、変わっていく中で、弊方でも、
A8: あるべき姿を神戸税関や関係者と協議してきました。TIVNｂの100項目に細分化された業務内容を
A9: 1項目ずつ検討した結果、6項目が評価加算を要する課税対象とすべき内容と判断されたたため、
A10: 12月より評価加算をお願いいたします。つきましては、詳細を下記いたしますので、ご確認願います。
A12: （１）評価加算すべき委託業務 6/100 項目 （神戸税関 包括評価申請にて以下項目について了承済み）
A21: （２）評価加算すべき額（2023年度）
A22: APIC： | B22: ='参考_APIC(2023年度) '!AV113*1000 -> 22915.059 | C22: /年 | D22: =B22/500000 -> 0.045830118 | E22: /50万着/年≒$0.05/着★
A23: BTNB： | B23: ='参考_BTNB(2023年度) '!AT114*1000 -> 6243.8232 | C23: /年 | D23: =B23/450000 -> 0.013875163 | E23: /45万着/年≒$0.02/着★
A24: ※生産計画から減産したことを考慮し、過少申告とならない様に、按分する着数を低めに設定。
A25: （APIC50万着、BTNB45万着) 更に､第三国向け分は考慮せず、係る全額を日本向けにて評価加算。
A26: ※上記の額が原価や工賃に加算されるわけではなく、あくまでも課税対象の額となります。
A27: 但し、有税の事案については、上記に関税率を乗じた額が原価に加わることとなります。
A28: ※年間の評価すべき額の算定については同Excelファイル内の参考シート参照
A30: （３）評価加算申告方法
A31: インボイスと一緒に評価加算要のエビデンスが皆様に届きますので、乙仲に、インボイスと一緒に
A32: 渡してください。申告額への加算ではなく、評価加算額に計上されるようにお願いいたします。
A33: ※エビデンスはあくまでも通関用の資料ですので、支払わないでください。別途業務委託費用として
A34: 支払われている費用です。
I35: （同内容を入船ダイナミックシッピング、日新運輸、鴻池運輸に弊方より伝達予定。）
A37: （４）開始時期
A38: 2023年度は11月の相当費用を2023年12月の出荷分より評価加算が必要。
A39: 来年5月より2024年度分の新価格にて評価加算をしていくこととなる。
A40: (以前のものに関しては今年の事後調査で修正）
A42: ≪問合せ先：アパレル物流課 田中（TEL:080-1529-8014）≫
I43: 以 上

Sheet 20240130 TIVN議事録
I2: 45321
A4: APIC、BTNB生産の輸入におけるTIVNの業務委託費用 会議
A6: 日にち：1/30（火）10：30～
A7: 参加者：TIVN 井上副部長、Chanh課長、Thong課長
A8: TI アパレル事業企画推進課 長岡町、石坂さん/アパレル物流課 宇都宮課長、荒井課員、田中
A11: （１）評価加算すべき額（2023年度現行）と評価加算額達成の見通し
A12: APIC： | B12: 22915.059 | C12: /年 | D12: 0.045830118 | E12: /50万着/年≒$0.05★
A13: BTNB： | B13: 6243.8232 | C13: /年 | D13: 0.013875163 | E13: /45万着/年≒$0.02★
A14: 12-4月評価加算額 | B14: 12-4月分岐枚数 | C14: 12月 | D14: 1月 | E14: 2月 | F14: 3月 | G14: 4月 | H14: 12月-4月 | I14: 過剰枚数 | J14: 評価額
A15: =B13/12*5 -> 2601.593 | B15: =A15/0.02 -> 130079.65 | C15: 3379 | D15: 130000 | E15: 76000 | F15: 5000 | G15: ？ | H15: =C15+D15+E15+F15 -> 214379 | I15: =H15-B15 -> 84299.35 | J15: =H15/B15 -> 1.6480595
A16: =B12/12*5 -> 9547.9412 | B16: =A16/0.05 -> 190958.82 | C16: 99327 | D16: 105000 | E16: 9300 | F16: 75000 | G16: ？ | H16: =C16+D16+E16+F16 -> 288627 | I16: =H16-B16 -> 97668.175 | J16: =H16/B16 -> 1.511462
A17: ➡上記予定通りに進めば、課税価格に参入すべき評価加算額を達成できる見込み。
A19: （２）評価加算すべき額（2024年5月～2025年4月）
A20: APIC： | B20: 15929.308 | C20: /年 | D20: =B20/600000 -> 0.026548846 | E20: /60万着/年≒$0.03★ | G20: (APIC 0.05➡0.03）
A21: BTNB： | B21: 8549.4182 | C21: /年 | D21: =B21/500000 -> 0.017098836 | E21: /50万着/年≒$0.02★ | G21: (BTNBは変更なし）
A23: （３）BTNB | B23: 35000 | C23: レンタルミシン費用 の評価要否
A24: TIに請求がくる場合：要課税
A25: BTNB負担のまま ：貨物代金に含まれているとして評価加算不要
A26: ➡後者のため、何等かのアクションは不要
A28: （４）QN工場 業務委託費
A29: 日本人3名の役務に係る費用、23年度、24年度ともに発生。
A30: 業務内容のリストアップ資料はなし。今後、考えていかなくてはならない部分。
A31: 加算すべき費用があった場合、2024年10月のAPIC、BTNBにおけるTIVN業務委託費用の
A32: 包括評価申請と合わせて行うか
A34: （５）TIVN業務委託費用のうち加算すべき年間金額の算出方法
A35: Ⅰ.必要書類 a.予算策定資料_年間TIVN業務委託費用-USD表記版
A36: b.APIC・BTNB_TIVNスタッフ業務分析表/2024年度業務委託料配分
A38: Ⅱ.算出工程
A39: 工程１： | B39: 上記Ⅰ.aに記載の数値をbの以下上部にある表に当て込む
J45: 以上
B47: 注：①＝2024年度はTIVN日本人スタッフ$743÷4名＝＄180.75/人を各工場に配分
B48: ②=2024年度はAPIC：295.83÷13名＝$22.76、BTNB：$335.87÷11名＝$30.53
B49: ③＝2024年度はAPIC：＄91.50、BTNB：＄91.50
A50: 工程２： | B50: 工数は当ファイル内2024年度のbの資料より自動で入力される形式にしているが、
B51: 念のため確認する
A52: 工程３： | B52: 小計の自動計算が合っているか確認する
A53: 工程４： | B53: 工程３で算出された総計と業務分析表の総計が一致しているか確認
A54: 工程５： | B54: 業務分析表の右端最下部の課税価格参入金額総計が各工場､1年当りの評価加算額(自動計算)となる｡
A55: 工程６： | B55: 工程５の数値が千USD単位なので、1000を乗じる
A56: 工程７： | B56: 工程6の数値を年間生産枚数で除算（上記（１）、（２）参照）し当該年度の1着当りの加算単価の算出完了。

Sheet 参考b_APIC(2024年度)
M1: 工数 | O1: 金額（千USD）※１ | AW1: 45320
A2: (予算ヒアリング補足資料からの編集版） | O2: 一人当たり | R2: 小計 | V2: 295.83 | Y2: 91.5 | AX2: Toray International Vietnam Co., Ltd
I3: 日本人管理者 | M3: =K12 -> 1 | O3: 180.75 | R3: =M3*O3 -> 180.75 | V3: =V2/13 -> 22.756154
I4: ナショナルスタッフ/管理グループ | M4: 8 | O4: =V3 -> 22.756154 | R4: =M4*O4 -> 182.04923
A5: APIC TIVNスタッフ業務分析表/2024年度業務委託料配分 | I5: ナショナルスタッフ/技術グループ | M5: =AO12 -> 5 | O5: =V3 -> 22.756154 | R5: =M5*O5 -> 113.78077 | U5: ※1：資料「(1)②TIVN業務委託費用配分」より抜粋
I6: TIVN本社ﾏﾈｰｼﾞﾒﾝﾄ※2 | M6: 1 | O6: =R6/M6 -> 91.5 | R6: 91.5 | U6: ※2：出張アテンドや配車手配
I7: 合計 | M7: =SUM(M3:N6) -> 15 | O7: - | R7: =SUM(R3:T6) -> 568.08 | U7: → | V7: =R7/12 -> 47.34 | W7: /月 | X7: ≒ | Y7: =V7*1000*135 -> 6390900 | AA7: /月(\135/USD換算）
AX8: 単位/千USD
G9: 日本人管理者 | M9: 管理グループ | AE9: 技術グループ | AQ9: TIVN本社ﾏﾈｰｼﾞﾒﾝﾄ(出張･配車手配） | AU9: 総計
G10: Inoue | K10: 計 | M10: Chanh | O10: Cuong | Q10: Hien | S10: Huy | U10: Khanh | W10: Luan | Y10: Nhu | AA10: Cau | AC10: 計 | AE10: Vy | AG10: Quyen | AI10: Hong | AK10: Phuong | AM10: Luu | AO10: 計 | AQ10: - | AS10: 計
G11: 工数 | H11: 金額 | I11: 工数 | J11: 金額 | K11: 工数 | L11: 金額 | M11: 工数 | N11: 金額 | O11: 工数 | P11: 金額 | Q11: 工数 | R11: 金額 | S11: 工数 | T11: 金額 | U11: 工数 | V11: 金額 | W11: 工数 | X11: 金額 | Y11: 工数 | Z11: 金額 | AA11: 工数 | AB11: 金額 | AC11: 工数 | AD11: 金額 | AE11: 工数 | AF11: 金額 | AG11: 工数 | AH11: 金額 | AI11: 工数 | AJ11: 金額 | AK11: 工数 | AL11: 金額 | AM11: 工数 | AN11: 金額 | AO11: 工数 | AP11: 金額 | AQ11: 工数 | AR11: 金額 | AS11: 工数 | AT11: 金額 | AU11: 工数 | AV11: 金額 | AW11: 該否 | AX11: 課税価格参入金額
A12: 分類 | B12: 工程 | D12: 作業 | E12: 作業内容 | F12: 発生頻度 | G12: 1 | H12: =O3 -> 180.75 | K12: =G12+I12 -> 1 | L12: =H12+J12 -> 180.75 | M12: 1 | N12: =O4 -> 22.756154 | O12: 1 | P12: =O4 -> 22.756154 | Q12: 1 | R12: =O4 -> 22.756154 | S12: 1 | T12: =O4 -> 22.756154 | U12: 1 | V12: =O4 -> 22.756154 | W12: 1 | X12: =O4 -> 22.756154 | Y12: 1 | Z12: =O4 -> 22.756154 | AA12: 1 | AB12: =O4 -> 22.756154 | AC12: =M4 -> 8 | AD12: =N12+P12+R12+T12+V12+X12+Z12+AB12 -> 182.04923 | AE12: 1 | AF12: =O5 -> 22.756154 | AG12: 1 | AH12: =O5 -> 22.756154 | AI12: 1 | AJ12: =O5 -> 22.756154 | AK12: 1 | AL12: =O5 -> 22.756154 | AM12: 1 | AN12: =O5 -> 22.756154 | AO12: =AE12+AG12+AK12+AM12+AI12 -> 5 | AP12: =AF12+AH12+AL12+AN12+AJ12 -> 113.78077 | AQ12: 1 | AR12: =O6 -> 91.5 | AS12: =AQ12 -> 1 | AT12: =AR12 -> 91.5 | AU12: =K12+AC12+AO12+AS12 -> 15 | AV12: =L12+AD12+AP12+AT12 -> 568.08
A13: 総括 | B13: 契約管理 | C13: 1 | D13: Debit Note | E13: Debit Note確認、実績踏まえ更新交渉 | F13: 月次 | H13: =$H$12/$G$12*G13 -> 0 | K13: =G13+I13 -> 0 | L13: =H13+J13 -> 0 | M13: 0.01 | N13: =N$12/M$12*M13 -> 0.22756154 | P13: =P$12/O$12*O13 -> 0 | R13: =R$12/Q$12*Q13 -> 0 | T13: =T$12/S$12*S13 -> 0 | V13: =V$12/U$12*U13 -> 0 | X13: =X$12/W$12*W13 -> 0 | Y13: 0.01 | Z13: =Z$12/Y$12*Y13 -> 0.22756154 | AB13: =AB$12/AA$12*AA13 -> 0 | AC13: =M13+O13+Q13+S13+U13+W13+Y13+AA13 -> 0.02 | AD13: =N13+P13+R13+T13+V13+X13+Z13+AB13 -> 0.45512308 | AF13: =AF$12/AE$12*AE13 -> 0 | AH13: =AH$12/AG$12*AG13 -> 0 | AJ13: =AJ$12/AI$12*AI13 -> 0 | AL13: =AL$12/AK$12*AK13 -> 0 | AN13: =AN$12/AM$12*AM13 -> 0 | AO13: =AE13+AG13+AK13+AM13+AI13 -> 0 | AP13: =AF13+AH13+AL13+AN13+AJ13 -> 0 | AS13: =AQ13 -> 0 | AT13: =AR13 -> 0 | AU13: =K13+AC13+AO13 -> 0.02 | AV13: =L13+AD13+AP13+AT13 -> 0.45512308 | AW13: - | AX13: =IF(AW13="●",AV13,0) -> 0 | AZ13: ●
B14: 交渉 | C14: 2 | D14: 出勤管理 | E14: 月ごとの出勤状況をまとめる | F14: 月次 | H14: =$H$12/$G$12*G14 -> 0 | K14: =G14+I14 -> 0 | L14: =H14+J14 -> 0 | N14: =N$12/M$12*M14 -> 0 | P14: =P$12/O$12*O14 -> 0 | R14: =R$12/Q$12*Q14 -> 0 | T14: =T$12/S$12*S14 -> 0 | V14: =V$12/U$12*U14 -> 0 | X14: =X$12/W$12*W14 -> 0 | Z14: =Z$12/Y$12*Y14 -> 0 | AB14: =AB$12/AA$12*AA14 -> 0 | AC14: =M14+O14+Q14+S14+U14+W14+Y14+AA14 -> 0 | AD14: =N14+P14+R14+T14+V14+X14+Z14+AB14 -> 0 | AF14: =AF$12/AE$12*AE14 -> 0 | AH14: =AH$12/AG$12*AG14 -> 0 | AJ14: =AJ$12/AI$12*AI14 -> 0 | AL14: =AL$12/AK$12*AK14 -> 0 | AN14: =AN$12/AM$12*AM14 -> 0 | AO14: =AE14+AG14+AK14+AM14+AI14 -> 0 | AP14: =AF14+AH14+AL14+AN14+AJ14 -> 0 | AS14: =AQ14 -> 0 | AT14: =AR14 -> 0 | AU14: =K14+AC14+AO14 -> 0 | AV14: =L14+AD14+AP14+AT14 -> 0 | AW14: - | AX14: =IF(AW14="●",AV14,0) -> 0 | AZ14: -
C15: 3 | D15: 期中変更対応 | E15: 工場からの業務内容変更要請対応 | F15: 不定期（頻度低） | G15: 0.01 | H15: =$H$12/$G$12*G15 -> 1.8075 | K15: =G15+I15 -> 0.01 | L15: =H15+J15 -> 1.8075 | M15: 0.01 | N15: =N$12/M$12*M15 -> 0.22756154 | P15: =P$12/O$12*O15 -> 0 | R15: =R$12/Q$12*Q15 -> 0 | T15: =T$12/S$12*S15 -> 0 | V15: =V$12/U$12*U15 -> 0 | X15: =X$12/W$12*W15 -> 0 | Z15: =Z$12/Y$12*Y15 -> 0 | AB15: =AB$12/AA$12*AA15 -> 0 | AC15: =M15+O15+Q15+S15+U15+W15+Y15+AA15 -> 0.01 | AD15: =N15+P15+R15+T15+V15+X15+Z15+AB15 -> 0.22756154 | AF15: =AF$12/AE$12*AE15 -> 0 | AH15: =AH$12/AG$12*AG15 -> 0 | AJ15: =AJ$12/AI$12*AI15 -> 0 | AL15: =AL$12/AK$12*AK15 -> 0 | AN15: =AN$12/AM$12*AM15 -> 0 | AO15: =AE15+AG15+AK15+AM15+AI15 -> 0 | AP15: =AF15+AH15+AL15+AN15+AJ15 -> 0 | AS15: =AQ15 -> 0 | AT15: =AR15 -> 0 | AU15: =K15+AC15+AO15 -> 0.02 | AV15: =L15+AD15+AP15+AT15 -> 2.0350615 | AW15: - | AX15: =IF(AW15="●",AV15,0) -> 0
C16: 4 | D16: 生産計画調整 | E16: 工場との生産計画調整・決定 | F16: 週次 | G16: 0.08 | H16: =$H$12/$G$12*G16 -> 14.46 | K16: =G16+I16 -> 0.08 | L16: =H16+J16 -> 14.46 | M16: 0.01 | N16: =N$12/M$12*M16 -> 0.22756154 | P16: =P$12/O$12*O16 -> 0 | R16: =R$12/Q$12*Q16 -> 0 | T16: =T$12/S$12*S16 -> 0 | V16: =V$12/U$12*U16 -> 0 | X16: =X$12/W$12*W16 -> 0 | Z16: =Z$12/Y$12*Y16 -> 0 | AB16: =AB$12/AA$12*AA16 -> 0 | AC16: =M16+O16+Q16+S16+U16+W16+Y16+AA16 -> 0.01 | AD16: =N16+P16+R16+T16+V16+X16+Z16+AB16 -> 0.22756154 | AF16: =AF$12/AE$12*AE16 -> 0 | AH16: =AH$12/AG$12*AG16 -> 0 | AJ16: =AJ$12/AI$12*AI16 -> 0 | AL16: =AL$12/AK$12*AK16 -> 0 | AN16: =AN$12/AM$12*AM16 -> 0 | AO16: =AE16+AG16+AK16+AM16+AI16 -> 0 | AP16: =AF16+AH16+AL16+AN16+AJ16 -> 0 | AS16: =AQ16 -> 0 | AT16: =AR16 -> 0 | AU16: =K16+AC16+AO16 -> 0.09 | AV16: =L16+AD16+AP16+AT16 -> 14.687562 | AW16: - | AX16: =IF(AW16="●",AV16,0) -> 0
C17: 5 | D17: 残業要請 | F17: 不定期（頻度低） | G17: 0.01 | H17: =$H$12/$G$12*G17 -> 1.8075 | K17: =G17+I17 -> 0.01 | L17: =H17+J17 -> 1.8075 | M17: 0.01 | N17: =N$12/M$12*M17 -> 0.22756154 | P17: =P$12/O$12*O17 -> 0 | R17: =R$12/Q$12*Q17 -> 0 | T17: =T$12/S$12*S17 -> 0 | V17: =V$12/U$12*U17 -> 0 | X17: =X$12/W$12*W17 -> 0 | Z17: =Z$12/Y$12*Y17 -> 0 | AB17: =AB$12/AA$12*AA17 -> 0 | AC17: =M17+O17+Q17+S17+U17+W17+Y17+AA17 -> 0.01 | AD17: =N17+P17+R17+T17+V17+X17+Z17+AB17 -> 0.22756154 | AF17: =AF$12/AE$12*AE17 -> 0 | AH17: =AH$12/AG$12*AG17 -> 0 | AJ17: =AJ$12/AI$12*AI17 -> 0 | AL17: =AL$12/AK$12*AK17 -> 0 | AN17: =AN$12/AM$12*AM17 -> 0 | AO17: =AE17+AG17+AK17+AM17+AI17 -> 0 | AP17: =AF17+AH17+AL17+AN17+AJ17 -> 0 | AS17: =AQ17 -> 0 | AT17: =AR17 -> 0 | AU17: =K17+AC17+AO17 -> 0.02 | AV17: =L17+AD17+AP17+AT17 -> 2.0350615 | AW17: - | AX17: =IF(AW17="●",AV17,0) -> 0
C18: 6 | D18: Air代負担交渉 | F18: 不定期（頻度低） | G18: 0.01 | H18: =$H$12/$G$12*G18 -> 1.8075 | K18: =G18+I18 -> 0.01 | L18: =H18+J18 -> 1.8075 | M18: 0.01 | N18: =N$12/M$12*M18 -> 0.22756154 | P18: =P$12/O$12*O18 -> 0 | R18: =R$12/Q$12*Q18 -> 0 | T18: =T$12/S$12*S18 -> 0 | V18: =V$12/U$12*U18 -> 0 | X18: =X$12/W$12*W18 -> 0 | Z18: =Z$12/Y$12*Y18 -> 0 | AB18: =AB$12/AA$12*AA18 -> 0 | AC18: =M18+O18+Q18+S18+U18+W18+Y18+AA18 -> 0.01 | AD18: =N18+P18+R18+T18+V18+X18+Z18+AB18 -> 0.22756154 | AF18: =AF$12/AE$12*AE18 -> 0 | AH18: =AH$12/AG$12*AG18 -> 0 | AJ18: =AJ$12/AI$12*AI18 -> 0 | AL18: =AL$12/AK$12*AK18 -> 0 | AN18: =AN$12/AM$12*AM18 -> 0 | AO18: =AE18+AG18+AK18+AM18+AI18 -> 0 | AP18: =AF18+AH18+AL18+AN18+AJ18 -> 0 | AS18: =AQ18 -> 0 | AT18: =AR18 -> 0 | AU18: =K18+AC18+AO18 -> 0.02 | AV18: =L18+AD18+AP18+AT18 -> 2.0350615 | AW18: - | AX18: =IF(AW18="●",AV18,0) -> 0
C19: 7 | D19: 外注工賃交渉 | F19: 不定期（頻度低） | G19: 0.01 | H19: =$H$12/$G$12*G19 -> 1.8075 | K19: =G19+I19 -> 0.01 | L19: =H19+J19 -> 1.8075 | M19: 0.01 | N19: =N$12/M$12*M19 -> 0.22756154 | P19: =P$12/O$12*O19 -> 0 | R19: =R$12/Q$12*Q19 -> 0 | T19: =T$12/S$12*S19 -> 0 | V19: =V$12/U$12*U19 -> 0 | X19: =X$12/W$12*W19 -> 0 | Z19: =Z$12/Y$12*Y19 -> 0 | AB19: =AB$12/AA$12*AA19 -> 0 | AC19: =M19+O19+Q19+S19+U19+W19+Y19+AA19 -> 0.01 | AD19: =N19+P19+R19+T19+V19+X19+Z19+AB19 -> 0.22756154 | AF19: =AF$12/AE$12*AE19 -> 0 | AH19: =AH$12/AG$12*AG19 -> 0 | AJ19: =AJ$12/AI$12*AI19 -> 0 | AL19: =AL$12/AK$12*AK19 -> 0 | AN19: =AN$12/AM$12*AM19 -> 0 | AO19: =AE19+AG19+AK19+AM19+AI19 -> 0 | AP19: =AF19+AH19+AL19+AN19+AJ19 -> 0 | AS19: =AQ19 -> 0 | AT19: =AR19 -> 0 | AU19: =K19+AC19+AO19 -> 0.02 | AV19: =L19+AD19+AP19+AT19 -> 2.0350615 | AW19: - | AX19: =IF(AW19="●",AV19,0) -> 0
B20: AUDIT | C20: 8 | D20: 事前準備 | E20: 提出書類、工場指導 | F20: 不定期（頻度低） | H20: =$H$12/$G$12*G20 -> 0 | K20: =G20+I20 -> 0 | L20: =H20+J20 -> 0 | M20: 0.01 | N20: =N$12/M$12*M20 -> 0.22756154 | P20: =P$12/O$12*O20 -> 0 | R20: =R$12/Q$12*Q20 -> 0 | T20: =T$12/S$12*S20 -> 0 | V20: =V$12/U$12*U20 -> 0 | X20: =X$12/W$12*W20 -> 0 | Y20: 0.01 | Z20: =Z$12/Y$12*Y20 -> 0.22756154 | AB20: =AB$12/AA$12*AA20 -> 0 | AC20: =M20+O20+Q20+S20+U20+W20+Y20+AA20 -> 0.02 | AD20: =N20+P20+R20+T20+V20+X20+Z20+AB20 -> 0.45512308 | AF20: =AF$12/AE$12*AE20 -> 0 | AH20: =AH$12/AG$12*AG20 -> 0 | AJ20: =AJ$12/AI$12*AI20 -> 0 | AL20: =AL$12/AK$12*AK20 -> 0 | AN20: =AN$12/AM$12*AM20 -> 0 | AO20: =AE20+AG20+AK20+AM20+AI20 -> 0 | AP20: =AF20+AH20+AL20+AN20+AJ20 -> 0 | AS20: =AQ20 -> 0 | AT20: =AR20 -> 0 | AU20: =K20+AC20+AO20 -> 0.02 | AV20: =L20+AD20+AP20+AT20 -> 0.45512308 | AW20: - | AX20: =IF(AW20="●",AV20,0) -> 0
B21: ※１ | C21: 9 | D21: 当日対応 | F21: 不定期（頻度低） | G21: 0.01 | H21: =$H$12/$G$12*G21 -> 1.8075 | K21: =G21+I21 -> 0.01 | L21: =H21+J21 -> 1.8075 | M21: 0.01 | N21: =N$12/M$12*M21 -> 0.22756154 | P21: =P$12/O$12*O21 -> 0 | R21: =R$12/Q$12*Q21 -> 0 | T21: =T$12/S$12*S21 -> 0 | V21: =V$12/U$12*U21 -> 0 | X21: =X$12/W$12*W21 -> 0 | Y21: 0.01 | Z21: =Z$12/Y$12*Y21 -> 0.22756154 | AB21: =AB$12/AA$12*AA21 -> 0 | AC21: =M21+O21+Q21+S21+U21+W21+Y21+AA21 -> 0.02 | AD21: =N21+P21+R21+T21+V21+X21+Z21+AB21 -> 0.45512308 | AF21: =AF$12/AE$12*AE21 -> 0 | AH21: =AH$12/AG$12*AG21 -> 0 | AJ21: =AJ$12/AI$12*AI21 -> 0 | AL21: =AL$12/AK$12*AK21 -> 0 | AN21: =AN$12/AM$12*AM21 -> 0 | AO21: =AE21+AG21+AK21+AM21+AI21 -> 0 | AP21: =AF21+AH21+AL21+AN21+AJ21 -> 0 | AS21: =AQ21 -> 0 | AT21: =AR21 -> 0 | AU21: =K21+AC21+AO21 -> 0.03 | AV21: =L21+AD21+AP21+AT21 -> 2.2626231 | AW21: - | AX21: =IF(AW21="●",AV21,0) -> 0
B22: 来客、 | C22: 10 | D22: 移動 | E22: 車、ホテル手配 | F22: 不定期（頻度高） | G22: 0.01 | H22: =$H$12/$G$12*G22 -> 1.8075 | K22: =G22+I22 -> 0.01 | L22: =H22+J22 -> 1.8075 | M22: 0.01 | N22: =N$12/M$12*M22 -> 0.22756154 | P22: =P$12/O$12*O22 -> 0 | R22: =R$12/Q$12*Q22 -> 0 | T22: =T$12/S$12*S22 -> 0 | V22: =V$12/U$12*U22 -> 0 | X22: =X$12/W$12*W22 -> 0 | Z22: =Z$12/Y$12*Y22 -> 0 | AA22: 0.01 | AB22: =AB$12/AA$12*AA22 -> 0.22756154 | AC22: =M22+O22+Q22+S22+U22+W22+Y22+AA22 -> 0.02 | AD22: =N22+P22+R22+T22+V22+X22+Z22+AB22 -> 0.45512308 | AF22: =AF$12/AE$12*AE22 -> 0 | AH22: =AH$12/AG$12*AG22 -> 0 | AJ22: =AJ$12/AI$12*AI22 -> 0 | AL22: =AL$12/AK$12*AK22 -> 0 | AN22: =AN$12/AM$12*AM22 -> 0 | AO22: =AE22+AG22+AK22+AM22+AI22 -> 0 | AP22: =AF22+AH22+AL22+AN22+AJ22 -> 0 | AQ22: 0.5 | AR22: =$AR$12/$AQ$12*AQ22 -> 45.75 | AS22: =AQ22 -> 0.5 | AT22: =AR22 -> 45.75 | AU22: =K22+AC22+AO22 -> 0.03 | AV22: =L22+AD22+AP22+AT22 -> 48.012623 | AW22: - | AX22: =IF(AW22="●",AV22,0) -> 0
B23: 出張対応 | C23: 11 | D23: 工場アテンド | E23: 案内、食事 | F23: 不定期（頻度低） | G23: 0.05 | H23: =$H$12/$G$12*G23 -> 9.0375 | K23: =G23+I23 -> 0.05 | L23: =H23+J23 -> 9.0375 | M23: 0.01 | N23: =N$12/M$12*M23 -> 0.22756154 | P23: =P$12/O$12*O23 -> 0 | R23: =R$12/Q$12*Q23 -> 0 | T23: =T$12/S$12*S23 -> 0 | V23: =V$12/U$12*U23 -> 0 | X23: =X$12/W$12*W23 -> 0 | Z23: =Z$12/Y$12*Y23 -> 0 | AB23: =AB$12/AA$12*AA23 -> 0 | AC23: =M23+O23+Q23+S23+U23+W23+Y23+AA23 -> 0.01 | AD23: =N23+P23+R23+T23+V23+X23+Z23+AB23 -> 0.22756154 | AF23: =AF$12/AE$12*AE23 -> 0 | AG23: 0.05 | AH23: =AH$12/AG$12*AG23 -> 1.1378077 | AI23: 0.02 | AJ23: =AJ$12/AI$12*AI23 -> 0.45512308 | AK23: 0.03 | AL23: =AL$12/AK$12*AK23 -> 0.68268462 | AM23: 0.02 | AN23: =AN$12/AM$12*AM23 -> 0.45512308 | AO23: =AE23+AG23+AK23+AM23+AI23 -> 0.12 | AP23: =AF23+AH23+AL23+AN23+AJ23 -> 2.7307385 | AQ23: 0.5 | AR23: =$AR$12/$AQ$12*AQ23 -> 45.75 | AS23: =AQ23 -> 0.5 | AT23: =AR23 -> 45.75 | AU23: =K23+AC23+AO23 -> 0.18 | AV23: =L23+AD23+AP23+AT23 -> 57.7458 | AW23: - | AX23: =IF(AW23="●",AV23,0) -> 0
C24: 12 | D24: 安全管理 | E24: 行程把握、緊急時対応 | F24: 不定期（頻度高） | G24: 0.05 | H24: =$H$12/$G$12*G24 -> 9.0375 | K24: =G24+I24 -> 0.05 | L24: =H24+J24 -> 9.0375 | M24: 0.01 | N24: =N$12/M$12*M24 -> 0.22756154 | P24: =P$12/O$12*O24 -> 0 | R24: =R$12/Q$12*Q24 -> 0 | T24: =T$12/S$12*S24 -> 0 | V24: =V$12/U$12*U24 -> 0 | X24: =X$12/W$12*W24 -> 0 | Z24: =Z$12/Y$12*Y24 -> 0 | AB24: =AB$12/AA$12*AA24 -> 0 | AC24: =M24+O24+Q24+S24+U24+W24+Y24+AA24 -> 0.01 | AD24: =N24+P24+R24+T24+V24+X24+Z24+AB24 -> 0.22756154 | AF24: =AF$12/AE$12*AE24 -> 0 | AH24: =AH$12/AG$12*AG24 -> 0 | AJ24: =AJ$12/AI$12*AI24 -> 0 | AL24: =AL$12/AK$12*AK24 -> 0 | AN24: =AN$12/AM$12*AM24 -> 0 | AO24: =AE24+AG24+AK24+AM24+AI24 -> 0 | AP24: =AF24+AH24+AL24+AN24+AJ24 -> 0 | AS24: =AQ24 -> 0 | AT24: =AR24 -> 0 | AU24: =K24+AC24+AO24 -> 0.06 | AV24: =L24+AD24+AP24+AT24 -> 9.2650615 | AW24: - | AX24: =IF(AW24="●",AV24,0) -> 0
A25: 企画 | B25: 開発 | C25: 13 | D25: 商品開発 | E25: 新規素材、加工技術調査、サンプル試作 | F25: 不定期（頻度中） | H25: =$H$12/$G$12*G25 -> 0 | K25: =G25+I25 -> 0 | L25: =H25+J25 -> 0 | N25: =N$12/M$12*M25 -> 0 | P25: =P$12/O$12*O25 -> 0 | R25: =R$12/Q$12*Q25 -> 0 | T25: =T$12/S$12*S25 -> 0 | V25: =V$12/U$12*U25 -> 0 | X25: =X$12/W$12*W25 -> 0 | Z25: =Z$12/Y$12*Y25 -> 0 | AA25: 0.02 | AB25: =AB$12/AA$12*AA25 -> 0.45512308 | AC25: =M25+O25+Q25+S25+U25+W25+Y25+AA25 -> 0.02 | AD25: =N25+P25+R25+T25+V25+X25+Z25+AB25 -> 0.45512308 | AF25: =AF$12/AE$12*AE25 -> 0 | AH25: =AH$12/AG$12*AG25 -> 0 | AJ25: =AJ$12/AI$12*AI25 -> 0 | AL25: =AL$12/AK$12*AK25 -> 0 | AN25: =AN$12/AM$12*AM25 -> 0 | AO25: =AE25+AG25+AK25+AM25+AI25 -> 0 | AP25: =AF25+AH25+AL25+AN25+AJ25 -> 0 | AS25: =AQ25 -> 0 | AT25: =AR25 -> 0 | AU25: =K25+AC25+AO25 -> 0.02 | AV25: =L25+AD25+AP25+AT25 -> 0.45512308 | AW25: ● | AX25: =IF(AW25="●",AV25,0) -> 0.45512308
C26: 14 | D26: 加工技術 | E26: 溶着縫製、パターン自動機、ダウン充填機設計 | F26: 不定期（頻度中） | H26: =$H$12/$G$12*G26 -> 0 | K26: =G26+I26 -> 0 | L26: =H26+J26 -> 0 | N26: =N$12/M$12*M26 -> 0 | P26: =P$12/O$12*O26 -> 0 | R26: =R$12/Q$12*Q26 -> 0 | T26: =T$12/S$12*S26 -> 0 | V26: =V$12/U$12*U26 -> 0 | X26: =X$12/W$12*W26 -> 0 | Z26: =Z$12/Y$12*Y26 -> 0 | AA26: 0.01 | AB26: =AB$12/AA$12*AA26 -> 0.22756154 | AC26: =M26+O26+Q26+S26+U26+W26+Y26+AA26 -> 0.01 | AD26: =N26+P26+R26+T26+V26+X26+Z26+AB26 -> 0.22756154 | AF26: =AF$12/AE$12*AE26 -> 0 | AH26: =AH$12/AG$12*AG26 -> 0 | AJ26: =AJ$12/AI$12*AI26 -> 0 | AL26: =AL$12/AK$12*AK26 -> 0 | AN26: =AN$12/AM$12*AM26 -> 0 | AO26: =AE26+AG26+AK26+AM26+AI26 -> 0 | AP26: =AF26+AH26+AL26+AN26+AJ26 -> 0 | AS26: =AQ26 -> 0 | AT26: =AR26 -> 0 | AU26: =K26+AC26+AO26 -> 0.01 | AV26: =L26+AD26+AP26+AT26 -> 0.22756154 | AW26: ● | AX26: =IF(AW26="●",AV26,0) -> 0.22756154
C27: 15 | D27: 生産技術 | E27: IE、ライン設計 | F27: 不定期（頻度低） | H27: =$H$12/$G$12*G27 -> 0 | K27: =G27+I27 -> 0 | L27: =H27+J27 -> 0 | N27: =N$12/M$12*M27 -> 0 | P27: =P$12/O$12*O27 -> 0 | R27: =R$12/Q$12*Q27 -> 0 | T27: =T$12/S$12*S27 -> 0 | V27: =V$12/U$12*U27 -> 0 | X27: =X$12/W$12*W27 -> 0 | Z27: =Z$12/Y$12*Y27 -> 0 | AA27: 0.01 | AB27: =AB$12/AA$12*AA27 -> 0.22756154 | AC27: =M27+O27+Q27+S27+U27+W27+Y27+AA27 -> 0.01 | AD27: =N27+P27+R27+T27+V27+X27+Z27+AB27 -> 0.22756154 | AF27: =AF$12/AE$12*AE27 -> 0 | AH27: =AH$12/AG$12*AG27 -> 0 | AJ27: =AJ$12/AI$12*AI27 -> 0 | AL27: =AL$12/AK$12*AK27 -> 0 | AN27: =AN$12/AM$12*AM27 -> 0 | AO27: =AE27+AG27+AK27+AM27+AI27 -> 0 | AP27: =AF27+AH27+AL27+AN27+AJ27 -> 0 | AS27: =AQ27 -> 0 | AT27: =AR27 -> 0 | AU27: =K27+AC27+AO27 -> 0.01 | AV27: =L27+AD27+AP27+AT27 -> 0.22756154 | AW27: ● | AX27: =IF(AW27="●",AV27,0) -> 0.22756154
C28: 16 | D28: 管理技術 | E28: 工程分析、進捗ばらつき、QC管理手法 | F28: 不定期（頻度中） | H28: =$H$12/$G$12*G28 -> 0 | K28: =G28+I28 -> 0 | L28: =H28+J28 -> 0 | N28: =N$12/M$12*M28 -> 0 | P28: =P$12/O$12*O28 -> 0 | R28: =R$12/Q$12*Q28 -> 0 | T28: =T$12/S$12*S28 -> 0 | V28: =V$12/U$12*U28 -> 0 | X28: =X$12/W$12*W28 -> 0 | Z28: =Z$12/Y$12*Y28 -> 0 | AA28: 0.02 | AB28: =AB$12/AA$12*AA28 -> 0.45512308 | AC28: =M28+O28+Q28+S28+U28+W28+Y28+AA28 -> 0.02 | AD28: =N28+P28+R28+T28+V28+X28+Z28+AB28 -> 0.45512308 | AF28: =AF$12/AE$12*AE28 -> 0 | AH28: =AH$12/AG$12*AG28 -> 0 | AJ28: =AJ$12/AI$12*AI28 -> 0 | AL28: =AL$12/AK$12*AK28 -> 0 | AN28: =AN$12/AM$12*AM28 -> 0 | AO28: =AE28+AG28+AK28+AM28+AI28 -> 0 | AP28: =AF28+AH28+AL28+AN28+AJ28 -> 0 | AS28: =AQ28 -> 0 | AT28: =AR28 -> 0 | AU28: =K28+AC28+AO28 -> 0.02 | AV28: =L28+AD28+AP28+AT28 -> 0.45512308 | AW28: - | AX28: =IF(AW28="●",AV28,0) -> 0
C29: 17 | D29: 評価技術 | E29: 機能性評価、商品評価、物性試験等 | F29: 不定期（頻度中） | H29: =$H$12/$G$12*G29 -> 0 | K29: =G29+I29 -> 0 | L29: =H29+J29 -> 0 | N29: =N$12/M$12*M29 -> 0 | P29: =P$12/O$12*O29 -> 0 | R29: =R$12/Q$12*Q29 -> 0 | T29: =T$12/S$12*S29 -> 0 | V29: =V$12/U$12*U29 -> 0 | X29: =X$12/W$12*W29 -> 0 | Z29: =Z$12/Y$12*Y29 -> 0 | AA29: 0.01 | AB29: =AB$12/AA$12*AA29 -> 0.22756154 | AC29: =M29+O29+Q29+S29+U29+W29+Y29+AA29 -> 0.01 | AD29: =N29+P29+R29+T29+V29+X29+Z29+AB29 -> 0.22756154 | AF29: =AF$12/AE$12*AE29 -> 0 | AH29: =AH$12/AG$12*AG29 -> 0 | AJ29: =AJ$12/AI$12*AI29 -> 0 | AL29: =AL$12/AK$12*AK29 -> 0 | AN29: =AN$12/AM$12*AM29 -> 0 | AO29: =AE29+AG29+AK29+AM29+AI29 -> 0 | AP29: =AF29+AH29+AL29+AN29+AJ29 -> 0 | AS29: =AQ29 -> 0 | AT29: =AR29 -> 0 | AU29: =K29+AC29+AO29 -> 0.01 | AV29: =L29+AD29+AP29+AT29 -> 0.22756154 | AW29: ● | AX29: =IF(AW29="●",AV29,0) -> 0.22756154
A30: 前段取り | B30: 生産計画 | C30: 18 | D30: プランテーブル | E30: 長期生産計画 | F30: 週次 | G30: 0.02 | H30: =$H$12/$G$12*G30 -> 3.615 | K30: =G30+I30 -> 0.02 | L30: =H30+J30 -> 3.615 | M30: 0.05 | N30: =N$12/M$12*M30 -> 1.1378077 | P30: =P$12/O$12*O30 -> 0 | R30: =R$12/Q$12*Q30 -> 0 | T30: =T$12/S$12*S30 -> 0 | V30: =V$12/U$12*U30 -> 0 | X30: =X$12/W$12*W30 -> 0 | Z30: =Z$12/Y$12*Y30 -> 0 | AB30: =AB$12/AA$12*AA30 -> 0 | AC30: =M30+O30+Q30+S30+U30+W30+Y30+AA30 -> 0.05 | AD30: =N30+P30+R30+T30+V30+X30+Z30+AB30 -> 1.1378077 | AF30: =AF$12/AE$12*AE30 -> 0 | AH30: =AH$12/AG$12*AG30 -> 0 | AJ30: =AJ$12/AI$12*AI30 -> 0 | AL30: =AL$12/AK$12*AK30 -> 0 | AN30: =AN$12/AM$12*AM30 -> 0 | AO30: =AE30+AG30+AK30+AM30+AI30 -> 0 | AP30: =AF30+AH30+AL30+AN30+AJ30 -> 0 | AS30: =AQ30 -> 0 | AT30: =AR30 -> 0 | AU30: =K30+AC30+AO30 -> 0.07 | AV30: =L30+AD30+AP30+AT30 -> 4.7528077 | AW30: - | AX30: =IF(AW30="●",AV30,0) -> 0
C31: 19 | D31: 明細連絡 | E31: SKU明細を工場へ連絡する | F31: 日次 | H31: =$H$12/$G$12*G31 -> 0 | K31: =G31+I31 -> 0 | L31: =H31+J31 -> 0 | M31: 0.01 | N31: =N$12/M$12*M31 -> 0.22756154 | O31: 0.01 | P31: =P$12/O$12*O31 -> 0.22756154 | Q31: 0.01 | R31: =R$12/Q$12*Q31 -> 0.22756154 | S31: 0.01 | T31: =T$12/S$12*S31 -> 0.22756154 | U31: 0.01 | V31: =V$12/U$12*U31 -> 0.22756154 | W31: 0.01 | X31: =X$12/W$12*W31 -> 0.22756154 | Y31: 0.01 | Z31: =Z$12/Y$12*Y31 -> 0.22756154 | AB31: =AB$12/AA$12*AA31 -> 0 | AC31: =M31+O31+Q31+S31+U31+W31+Y31+AA31 -> 0.07 | AD31: =N31+P31+R31+T31+V31+X31+Z31+AB31 -> 1.5929308 | AF31: =AF$12/AE$12*AE31 -> 0 | AH31: =AH$12/AG$12*AG31 -> 0 | AJ31: =AJ$12/AI$12*AI31 -> 0 | AL31: =AL$12/AK$12*AK31 -> 0 | AN31: =AN$12/AM$12*AM31 -> 0 | AO31: =AE31+AG31+AK31+AM31+AI31 -> 0 | AP31: =AF31+AH31+AL31+AN31+AJ31 -> 0 | AS31: =AQ31 -> 0 | AT31: =AR31 -> 0 | AU31: =K31+AC31+AO31 -> 0.07 | AV31: =L31+AD31+AP31+AT31 -> 1.5929308 | AW31: - | AX31: =IF(AW31="●",AV31,0) -> 0
C32: 20 | D32: 工場生産計画 | E32: 中期生産計画 | F32: 週次 | G32: 0.02 | H32: =$H$12/$G$12*G32 -> 3.615 | K32: =G32+I32 -> 0.02 | L32: =H32+J32 -> 3.615 | M32: 0.04 | N32: =N$12/M$12*M32 -> 0.91024615 | P32: =P$12/O$12*O32 -> 0 | R32: =R$12/Q$12*Q32 -> 0 | T32: =T$12/S$12*S32 -> 0 | V32: =V$12/U$12*U32 -> 0 | X32: =X$12/W$12*W32 -> 0 | Z32: =Z$12/Y$12*Y32 -> 0 | AB32: =AB$12/AA$12*AA32 -> 0 | AC32: =M32+O32+Q32+S32+U32+W32+Y32+AA32 -> 0.04 | AD32: =N32+P32+R32+T32+V32+X32+Z32+AB32 -> 0.91024615 | AF32: =AF$12/AE$12*AE32 -> 0 | AH32: =AH$12/AG$12*AG32 -> 0 | AJ32: =AJ$12/AI$12*AI32 -> 0 | AL32: =AL$12/AK$12*AK32 -> 0 | AN32: =AN$12/AM$12*AM32 -> 0 | AO32: =AE32+AG32+AK32+AM32+AI32 -> 0 | AP32: =AF32+AH32+AL32+AN32+AJ32 -> 0 | AS32: =AQ32 -> 0 | AT32: =AR32 -> 0 | AU32: =K32+AC32+AO32 -> 0.06 | AV32: =L32+AD32+AP32+AT32 -> 4.5252462 | AW32: - | AX32: =IF(AW32="●",AV32,0) -> 0
C33: 21 | D33: 資材進捗 | E33: 材料の進捗状況を確認し工場へ報告する | F33: 日次 | H33: =$H$12/$G$12*G33 -> 0 | K33: =G33+I33 -> 0 | L33: =H33+J33 -> 0 | M33: 0.05 | N33: =N$12/M$12*M33 -> 1.1378077 | O33: 0.02 | P33: =P$12/O$12*O33 -> 0.45512308 | Q33: 0.02 | R33: =R$12/Q$12*Q33 -> 0.45512308 | S33: 0.02 | T33: =T$12/S$12*S33 -> 0.45512308 | U33: 0.02 | V33: =V$12/U$12*U33 -> 0.45512308 | W33: 0.05 | X33: =X$12/W$12*W33 -> 1.1378077 | Y33: 0.01 | Z33: =Z$12/Y$12*Y33 -> 0.22756154 | AB33: =AB$12/AA$12*AA33 -> 0 | AC33: =M33+O33+Q33+S33+U33+W33+Y33+AA33 -> 0.19 | AD33: =N33+P33+R33+T33+V33+X33+Z33+AB33 -> 4.3236692 | AF33: =AF$12/AE$12*AE33 -> 0 | AH33: =AH$12/AG$12*AG33 -> 0 | AJ33: =AJ$12/AI$12*AI33 -> 0 | AL33: =AL$12/AK$12*AK33 -> 0 | AN33: =AN$12/AM$12*AM33 -> 0 | AO33: =AE33+AG33+AK33+AM33+AI33 -> 0 | AP33: =AF33+AH33+AL33+AN33+AJ33 -> 0 | AS33: =AQ33 -> 0 | AT33: =AR33 -> 0 | AU33: =K33+AC33+AO33 -> 0.19 | AV33: =L33+AD33+AP33+AT33 -> 4.3236692 | AW33: - | AX33: =IF(AW33="●",AV33,0) -> 0
C34: 22 | D34: 注意連絡 | E34: 特別に注視する内容を工場へ連絡 | F34: 週次 | G34: 0.01 | H34: =$H$12/$G$12*G34 -> 1.8075 | K34: =G34+I34 -> 0.01 | L34: =H34+J34 -> 1.8075 | M34: 0.01 | N34: =N$12/M$12*M34 -> 0.22756154 | P34: =P$12/O$12*O34 -> 0 | R34: =R$12/Q$12*Q34 -> 0 | S34: 0.01 | T34: =T$12/S$12*S34 -> 0.22756154 | V34: =V$12/U$12*U34 -> 0 | X34: =X$12/W$12*W34 -> 0 | Z34: =Z$12/Y$12*Y34 -> 0 | AA34: 0.01 | AB34: =AB$12/AA$12*AA34 -> 0.22756154 | AC34: =M34+O34+Q34+S34+U34+W34+Y34+AA34 -> 0.03 | AD34: =N34+P34+R34+T34+V34+X34+Z34+AB34 -> 0.68268462 | AF34: =AF$12/AE$12*AE34 -> 0 | AG34: 0.01 | AH34: =AH$12/AG$12*AG34 -> 0.22756154 | AI34: 0.01 | AJ34: =AJ$12/AI$12*AI34 -> 0.22756154 | AL34: =AL$12/AK$12*AK34 -> 0 | AN34: =AN$12/AM$12*AM34 -> 0 | AO34: =AE34+AG34+AK34+AM34+AI34 -> 0.02 | AP34: =AF34+AH34+AL34+AN34+AJ34 -> 0.45512308 | AS34: =AQ34 -> 0 | AT34: =AR34 -> 0 | AU34: =K34+AC34+AO34 -> 0.06 | AV34: =L34+AD34+AP34+AT34 -> 2.9453077 | AW34: - | AX34: =IF(AW34="●",AV34,0) -> 0
B35: サンプル | C35: 23 | D35: 受注 | E35: 営業オーダー受注。サンプル管理表への記入 | F35: 日次 | H35: =$H$12/$G$12*G35 -> 0 | K35: =G35+I35 -> 0 | L35: =H35+J35 -> 0 | N35: =N$12/M$12*M35 -> 0 | O35: 0.02 | P35: =P$12/O$12*O35 -> 0.45512308 | Q35: 0.02 | R35: =R$12/Q$12*Q35 -> 0.45512308 | S35: 0.02 | T35: =T$12/S$12*S35 -> 0.45512308 | U35: 0.02 | V35: =V$12/U$12*U35 -> 0.45512308 | W35: 0.01 | X35: =X$12/W$12*W35 -> 0.22756154 | Y35: 0.01 | Z35: =Z$12/Y$12*Y35 -> 0.22756154 | AB35: =AB$12/AA$12*AA35 -> 0 | AC35: =M35+O35+Q35+S35+U35+W35+Y35+AA35 -> 0.1 | AD35: =N35+P35+R35+T35+V35+X35+Z35+AB35 -> 2.2756154 | AE35: 0.04 | AF35: =AF$12/AE$12*AE35 -> 0.91024615 | AH35: =AH$12/AG$12*AG35 -> 0 | AJ35: =AJ$12/AI$12*AI35 -> 0 | AL35: =AL$12/AK$12*AK35 -> 0 | AN35: =AN$12/AM$12*AM35 -> 0 | AO35: =AE35+AG35+AK35+AM35+AI35 -> 0.04 | AP35: =AF35+AH35+AL35+AN35+AJ35 -> 0.91024615 | AS35: =AQ35 -> 0 | AT35: =AR35 -> 0 | AU35: =K35+AC35+AO35 -> 0.14 | AV35: =L35+AD35+AP35+AT35 -> 3.1858615 | AW35: - | AX35: =IF(AW35="●",AV35,0) -> 0
C36: 24 | D36: 工場指示 | E36: 日本からのサンプル依頼を工場へ連絡 | F36: 日次 | G36: 0.01 | H36: =$H$12/$G$12*G36 -> 1.8075 | K36: =G36+I36 -> 0.01 | L36: =H36+J36 -> 1.8075 | N36: =N$12/M$12*M36 -> 0 | O36: 0.01 | P36: =P$12/O$12*O36 -> 0.22756154 | Q36: 0.01 | R36: =R$12/Q$12*Q36 -> 0.22756154 | S36: 0.01 | T36: =T$12/S$12*S36 -> 0.22756154 | U36: 0.01 | V36: =V$12/U$12*U36 -> 0.22756154 | W36: 0.01 | X36: =X$12/W$12*W36 -> 0.22756154 | Y36: 0.01 | Z36: =Z$12/Y$12*Y36 -> 0.22756154 | AB36: =AB$12/AA$12*AA36 -> 0 | AC36: =M36+O36+Q36+S36+U36+W36+Y36+AA36 -> 0.06 | AD36: =N36+P36+R36+T36+V36+X36+Z36+AB36 -> 1.3653692 | AF36: =AF$12/AE$12*AE36 -> 0 | AH36: =AH$12/AG$12*AG36 -> 0 | AJ36: =AJ$12/AI$12*AI36 -> 0 | AL36: =AL$12/AK$12*AK36 -> 0 | AN36: =AN$12/AM$12*AM36 -> 0 | AO36: =AE36+AG36+AK36+AM36+AI36 -> 0 | AP36: =AF36+AH36+AL36+AN36+AJ36 -> 0 | AS36: =AQ36 -> 0 | AT36: =AR36 -> 0 | AU36: =K36+AC36+AO36 -> 0.07 | AV36: =L36+AD36+AP36+AT36 -> 3.1728692 | AW36: - | AX36: =IF(AW36="●",AV36,0) -> 0
C37: 25 | D37: 納期回答 | E37: 工場スケジューリング、納期回答 | F37: 日次 | G37: 0.01 | H37: =$H$12/$G$12*G37 -> 1.8075 | K37: =G37+I37 -> 0.01 | L37: =H37+J37 -> 1.8075 | N37: =N$12/M$12*M37 -> 0 | O37: 0.01 | P37: =P$12/O$12*O37 -> 0.22756154 | Q37: 0.01 | R37: =R$12/Q$12*Q37 -> 0.22756154 | S37: 0.01 | T37: =T$12/S$12*S37 -> 0.22756154 | U37: 0.01 | V37: =V$12/U$12*U37 -> 0.22756154 | W37: 0.01 | X37: =X$12/W$12*W37 -> 0.22756154 | Y37: 0.01 | Z37: =Z$12/Y$12*Y37 -> 0.22756154 | AB37: =AB$12/AA$12*AA37 -> 0 | AC37: =M37+O37+Q37+S37+U37+W37+Y37+AA37 -> 0.06 | AD37: =N37+P37+R37+T37+V37+X37+Z37+AB37 -> 1.3653692 | AE37: 0.04 | AF37: =AF$12/AE$12*AE37 -> 0.91024615 | AH37: =AH$12/AG$12*AG37 -> 0 | AJ37: =AJ$12/AI$12*AI37 -> 0 | AL37: =AL$12/AK$12*AK37 -> 0 | AN37: =AN$12/AM$12*AM37 -> 0 | AO37: =AE37+AG37+AK37+AM37+AI37 -> 0.04 | AP37: =AF37+AH37+AL37+AN37+AJ37 -> 0.91024615 | AS37: =AQ37 -> 0 | AT37: =AR37 -> 0 | AU37: =K37+AC37+AO37 -> 0.11 | AV37: =L37+AD37+AP37+AT37 -> 4.0831154 | AW37: - | AX37: =IF(AW37="●",AV37,0) -> 0
C38: 26 | D38: 仕様 | E38: 仕様書の受領、翻訳 | F38: 日次 | H38: =$H$12/$G$12*G38 -> 0 | K38: =G38+I38 -> 0 | L38: =H38+J38 -> 0 | N38: =N$12/M$12*M38 -> 0 | O38: 0.14 | P38: =P$12/O$12*O38 -> 3.1858615 | Q38: 0.14 | R38: =R$12/Q$12*Q38 -> 3.1858615 | S38: 0.14 | T38: =T$12/S$12*S38 -> 3.1858615 | U38: 0.14 | V38: =V$12/U$12*U38 -> 3.1858615 | W38: 0.15 | X38: =X$12/W$12*W38 -> 3.4134231 | Y38: 0.05 | Z38: =Z$12/Y$12*Y38 -> 1.1378077 | AB38: =AB$12/AA$12*AA38 -> 0 | AC38: =M38+O38+Q38+S38+U38+W38+Y38+AA38 -> 0.76 | AD38: =N38+P38+R38+T38+V38+X38+Z38+AB38 -> 17.294677 | AF38: =AF$12/AE$12*AE38 -> 0 | AH38: =AH$12/AG$12*AG38 -> 0 | AJ38: =AJ$12/AI$12*AI38 -> 0 | AL38: =AL$12/AK$12*AK38 -> 0 | AN38: =AN$12/AM$12*AM38 -> 0 | AO38: =AE38+AG38+AK38+AM38+AI38 -> 0 | AP38: =AF38+AH38+AL38+AN38+AJ38 -> 0 | AS38: =AQ38 -> 0 | AT38: =AR38 -> 0 | AU38: =K38+AC38+AO38 -> 0.76 | AV38: =L38+AD38+AP38+AT38 -> 17.294677 | AW38: - | AX38: =IF(AW38="●",AV38,0) -> 0
C39: 27 | D39: パターンチェック | E39: パターンの受領、寸法チェック | F39: 日次 | H39: =$H$12/$G$12*G39 -> 0 | K39: =G39+I39 -> 0 | L39: =H39+J39 -> 0 | N39: =N$12/M$12*M39 -> 0 | O39: 0.01 | P39: =P$12/O$12*O39 -> 0.22756154 | Q39: 0.01 | R39: =R$12/Q$12*Q39 -> 0.22756154 | S39: 0.01 | T39: =T$12/S$12*S39 -> 0.22756154 | U39: 0.01 | V39: =V$12/U$12*U39 -> 0.22756154 | W39: 0.01 | X39: =X$12/W$12*W39 -> 0.22756154 | Y39: 0.01 | Z39: =Z$12/Y$12*Y39 -> 0.22756154 | AB39: =AB$12/AA$12*AA39 -> 0 | AC39: =M39+O39+Q39+S39+U39+W39+Y39+AA39 -> 0.06 | AD39: =N39+P39+R39+T39+V39+X39+Z39+AB39 -> 1.3653692 | AE39: 0.1 | AF39: =AF$12/AE$12*AE39 -> 2.2756154 | AH39: =AH$12/AG$12*AG39 -> 0 | AJ39: =AJ$12/AI$12*AI39 -> 0 | AL39: =AL$12/AK$12*AK39 -> 0 | AN39: =AN$12/AM$12*AM39 -> 0 | AO39: =AE39+AG39+AK39+AM39+AI39 -> 0.1 | AP39: =AF39+AH39+AL39+AN39+AJ39 -> 2.2756154 | AS39: =AQ39 -> 0 | AT39: =AR39 -> 0 | AU39: =K39+AC39+AO39 -> 0.16 | AV39: =L39+AD39+AP39+AT39 -> 3.6409846 | AW39: - | AX39: =IF(AW39="●",AV39,0) -> 0
C40: 28 | D40: 用尺計算 | E40: 工場の作成したマーカー図のチェック、修正依頼 | F40: 日次 | H40: =$H$12/$G$12*G40 -> 0 | K40: =G40+I40 -> 0 | L40: =H40+J40 -> 0 | N40: =N$12/M$12*M40 -> 0 | O40: 0.01 | P40: =P$12/O$12*O40 -> 0.22756154 | Q40: 0.01 | R40: =R$12/Q$12*Q40 -> 0.22756154 | S40: 0.01 | T40: =T$12/S$12*S40 -> 0.22756154 | U40: 0.01 | V40: =V$12/U$12*U40 -> 0.22756154 | W40: 0.01 | X40: =X$12/W$12*W40 -> 0.22756154 | Y40: 0.01 | Z40: =Z$12/Y$12*Y40 -> 0.22756154 | AB40: =AB$12/AA$12*AA40 -> 0 | AC40: =M40+O40+Q40+S40+U40+W40+Y40+AA40 -> 0.06 | AD40: =N40+P40+R40+T40+V40+X40+Z40+AB40 -> 1.3653692 | AF40: =AF$12/AE$12*AE40 -> 0 | AH40: =AH$12/AG$12*AG40 -> 0 | AJ40: =AJ$12/AI$12*AI40 -> 0 | AL40: =AL$12/AK$12*AK40 -> 0 | AN40: =AN$12/AM$12*AM40 -> 0 | AO40: =AE40+AG40+AK40+AM40+AI40 -> 0 | AP40: =AF40+AH40+AL40+AN40+AJ40 -> 0 | AS40: =AQ40 -> 0 | AT40: =AR40 -> 0 | AU40: =K40+AC40+AO40 -> 0.06 | AV40: =L40+AD40+AP40+AT40 -> 1.3653692 | AW40: - | AX40: =IF(AW40="●",AV40,0) -> 0
...

Sheet 参考b_BTNB(2024年度) 
M1: 工数 | O1: 金額（千USD）※１ | AU1: 45320
A2: (予算ヒアリング補足資料からの編集版） | O2: 一人当たり | R2: 小計 | W2: =W3/11 -> 30.533636 | AV2: Toray International Vietnam Co., Ltd
G3: 日本人管理者 | M3: =K13 -> 1 | O3: 180.75 | R3: =M3*O3 -> 180.75 | W3: 335.87
G4: ナショナルスタッフ/管理グループ | M4: =Y13 -> 6 | O4: =W2 -> 30.533636 | R4: =M4*O4 -> 183.20182
A5: BTNB TIVNスタッフ業務分析表/2024年度業務委託料配分 | G5: ナショナルスタッフ/技術グループ | M5: =AM13 -> 5 | O5: =W2 -> 30.533636 | R5: =M5*O5 -> 152.66818 | U5: ※1：資料「(1)②TIVN業務委託費用配分」より抜粋
G6: TIVN本社ﾏﾈｰｼﾞﾒﾝﾄ※2 | M6: 1 | O6: =R6 -> 91.5 | R6: 91.5 | U6: ※2：出張アテンドや配車手配 | AC6: 91.5
G7: 合計 | M7: =SUM(M3:N6) -> 13 | O7: - | R7: =SUM(R3:T6) -> 608.12 | U7: → | V7: =R7/12 -> 50.676667 | W7: /月 | X7: ≒ | Y7: =V7*1000*135 -> 6841350 | AA7: /月(\135/USD換算）
AV8: 単位/千USD
L9: ＊進捗管理スタッフは日本営業の現地サポート役と位置付けており、来客対応から各々が全てをブランド括りで業務処理をしている、
G10: 日本人管理者 | M10: 管理グループ | AA10: 技術グループ | AO10: TIVN本社ﾏﾈｰｼﾞﾒﾝﾄ(出張･配車手配） | AS10: 総計
G11: Naito | K11: 計 | M11: Thong | O11: Tuong | Q11: Nhi | S11: T_Van | U11: Tuan | W11: Trinh | Y11: 計 | AA11: H_Van | AC11: Chau | AE11: Minh | AG11: Thu | AI11: Hoa | AK11: NEW STAFF | AM11: 計 | AO11: - | AQ11: 計
G12: 工数 | H12: 金額 | I12: 工数 | J12: 金額 | K12: 工数 | L12: 金額 | M12: 工数 | N12: 金額 | O12: 工数 | P12: 金額 | Q12: 工数 | R12: 金額 | S12: 工数 | T12: 金額 | U12: 工数 | V12: 金額 | W12: 工数 | X12: 金額 | Y12: 工数 | Z12: 金額 | AA12: 工数 | AB12: 金額 | AC12: 工数 | AD12: 金額 | AE12: 工数 | AF12: 金額 | AG12: 工数 | AH12: 金額 | AI12: 工数 | AJ12: 金額 | AK12: 工数 | AL12: 金額 | AM12: 工数 | AN12: 金額 | AO12: 工数 | AP12: 金額 | AQ12: 工数 | AR12: 金額 | AS12: 工数 | AT12: 金額 | AU12: 該否 | AV12: 課税価格参入金額
A13: 分類 | B13: 工程 | D13: 作業 | E13: 作業内容 | F13: 発生頻度 | G13: 1 | H13: =O3 -> 180.75 | K13: =G13+I13 -> 1 | L13: =H13+J13 -> 180.75 | M13: 1 | N13: =O4 -> 30.533636 | O13: 1 | P13: =O4 -> 30.533636 | Q13: 1 | R13: =O4 -> 30.533636 | S13: 1 | T13: =O4 -> 30.533636 | U13: 1 | V13: =O4 -> 30.533636 | W13: 1 | X13: =O4 -> 30.533636 | Y13: =M13+O13+Q13+S13+U13+W13 -> 6 | Z13: =N13+P13+R13+T13+V13+X13 -> 183.20182 | AA13: 1 | AB13: =O5 -> 30.533636 | AC13: 1 | AD13: =O5 -> 30.533636 | AE13: 1 | AF13: =O5 -> 30.533636 | AG13: 1 | AH13: =O5 -> 30.533636 | AI13: 1 | AJ13: =O5 -> 30.533636 | AK13: 1 | AL13: =O5 -> 30.533636 | AM13: =AA13+AC13+AE13+AG13+AK13 -> 5 | AN13: =AB13+AD13+AF13+AH13+AL13 -> 152.66818 | AO13: 1 | AP13: =O6 -> 91.5 | AQ13: =AO13 -> 1 | AR13: =AP13 -> 91.5 | AS13: =K13+Y13+AM13+AQ13 -> 13 | AT13: =L13+Z13+AN13+AR13 -> 608.12
A14: 総括 | B14: 契約管理 | C14: 1 | D14: Debit Note | E14: Debit Note確認、実績踏まえ更新交渉 | F14: 月次 | G14: 0.01 | H14: =H$13/G$13*G14 -> 1.8075 | K14: =G14+I14 -> 0.01 | L14: =H14+J14 -> 1.8075 | M14: 0.02 | N14: =N$13/M$13*M14 -> 0.61067273 | P14: =P$13/O$13*O14 -> 0 | R14: =R$13/Q$13*Q14 -> 0 | T14: =T$13/S$13*S14 -> 0 | V14: =V$13/U$13*U14 -> 0 | X14: =X$13/W$13*W14 -> 0 | Y14: =M14+O14+Q14+S14+U14+W14 -> 0.02 | Z14: =N14+P14+R14+T14+V14+X14 -> 0.61067273 | AB14: =AB$13/AA$13*AA14 -> 0 | AD14: =AD$13/AC$13*AC14 -> 0 | AF14: =AF$13/AE$13*AE14 -> 0 | AH14: =AH$13/AG$13*AG14 -> 0 | AJ14: =AJ$13/AI$13*AI14 -> 0 | AL14: =AL$13/AK$13*AK14 -> 0 | AM14: =AA14+AC14+AE14+AG14+AK14 -> 0 | AN14: =AB14+AD14+AF14+AH14+AL14 -> 0 | AP14: =AP$13/AO$13*AO14 -> 0 | AQ14: =AO14 -> 0 | AR14: =AP14 -> 0 | AS14: =K14+Y14+AM14+AQ14 -> 0.03 | AT14: =L14+Z14+AN14+AR14 -> 2.4181727 | AU14: - | AV14: =IF(AU14="●",AT14,0) -> 0 | AX14: ●
B15: 交渉 | C15: 2 | D15: 出勤管理 | E15: 月ごとの出勤状況をまとめる | F15: 月次 | G15: 0.01 | H15: =H$13/G$13*G15 -> 1.8075 | K15: =G15+I15 -> 0.01 | L15: =H15+J15 -> 1.8075 | M15: 0.02 | N15: =N$13/M$13*M15 -> 0.61067273 | P15: =P$13/O$13*O15 -> 0 | R15: =R$13/Q$13*Q15 -> 0 | T15: =T$13/S$13*S15 -> 0 | V15: =V$13/U$13*U15 -> 0 | X15: =X$13/W$13*W15 -> 0 | Y15: =M15+O15+Q15+S15+U15+W15 -> 0.02 | Z15: =N15+P15+R15+T15+V15+X15 -> 0.61067273 | AB15: =AB$13/AA$13*AA15 -> 0 | AD15: =AD$13/AC$13*AC15 -> 0 | AF15: =AF$13/AE$13*AE15 -> 0 | AH15: =AH$13/AG$13*AG15 -> 0 | AJ15: =AJ$13/AI$13*AI15 -> 0 | AL15: =AL$13/AK$13*AK15 -> 0 | AM15: =AA15+AC15+AE15+AG15+AK15 -> 0 | AN15: =AB15+AD15+AF15+AH15+AL15 -> 0 | AP15: =AP$13/AO$13*AO15 -> 0 | AQ15: =AO15 -> 0 | AR15: =AP15 -> 0 | AS15: =K15+Y15+AM15+AQ15 -> 0.03 | AT15: =L15+Z15+AN15+AR15 -> 2.4181727 | AU15: - | AV15: =IF(AU15="●",AT15,0) -> 0 | AX15: -
C16: 3 | D16: 期中変更対応 | E16: 工場からの業務内容変更要請対応 | F16: 不定期（頻度低） | G16: 0.01 | H16: =H$13/G$13*G16 -> 1.8075 | K16: =G16+I16 -> 0.01 | L16: =H16+J16 -> 1.8075 | M16: 0.02 | N16: =N$13/M$13*M16 -> 0.61067273 | O16: 0.01 | P16: =P$13/O$13*O16 -> 0.30533636 | Q16: 0.01 | R16: =R$13/Q$13*Q16 -> 0.30533636 | S16: 0.01 | T16: =T$13/S$13*S16 -> 0.30533636 | U16: 0.01 | V16: =V$13/U$13*U16 -> 0.30533636 | W16: 0.01 | X16: =X$13/W$13*W16 -> 0.30533636 | Y16: =M16+O16+Q16+S16+U16+W16 -> 0.07 | Z16: =N16+P16+R16+T16+V16+X16 -> 2.1373545 | AB16: =AB$13/AA$13*AA16 -> 0 | AD16: =AD$13/AC$13*AC16 -> 0 | AF16: =AF$13/AE$13*AE16 -> 0 | AH16: =AH$13/AG$13*AG16 -> 0 | AJ16: =AJ$13/AI$13*AI16 -> 0 | AL16: =AL$13/AK$13*AK16 -> 0 | AM16: =AA16+AC16+AE16+AG16+AK16 -> 0 | AN16: =AB16+AD16+AF16+AH16+AL16 -> 0 | AP16: =AP$13/AO$13*AO16 -> 0 | AQ16: =AO16 -> 0 | AR16: =AP16 -> 0 | AS16: =K16+Y16+AM16+AQ16 -> 0.08 | AT16: =L16+Z16+AN16+AR16 -> 3.9448545 | AU16: - | AV16: =IF(AU16="●",AT16,0) -> 0
C17: 4 | D17: 生産計画調整 | E17: 工場との生産計画調整・決定 | F17: 週次 | G17: 0.4 | H17: =H$13/G$13*G17 -> 72.3 | K17: =G17+I17 -> 0.4 | L17: =H17+J17 -> 72.3 | M17: 0.02 | N17: =N$13/M$13*M17 -> 0.61067273 | P17: =P$13/O$13*O17 -> 0 | R17: =R$13/Q$13*Q17 -> 0 | T17: =T$13/S$13*S17 -> 0 | V17: =V$13/U$13*U17 -> 0 | X17: =X$13/W$13*W17 -> 0 | Y17: =M17+O17+Q17+S17+U17+W17 -> 0.02 | Z17: =N17+P17+R17+T17+V17+X17 -> 0.61067273 | AB17: =AB$13/AA$13*AA17 -> 0 | AD17: =AD$13/AC$13*AC17 -> 0 | AF17: =AF$13/AE$13*AE17 -> 0 | AH17: =AH$13/AG$13*AG17 -> 0 | AJ17: =AJ$13/AI$13*AI17 -> 0 | AL17: =AL$13/AK$13*AK17 -> 0 | AM17: =AA17+AC17+AE17+AG17+AK17 -> 0 | AN17: =AB17+AD17+AF17+AH17+AL17 -> 0 | AP17: =AP$13/AO$13*AO17 -> 0 | AQ17: =AO17 -> 0 | AR17: =AP17 -> 0 | AS17: =K17+Y17+AM17+AQ17 -> 0.42 | AT17: =L17+Z17+AN17+AR17 -> 72.910673 | AU17: - | AV17: =IF(AU17="●",AT17,0) -> 0
C18: 5 | D18: Air代負担交渉 | F18: 不定期（頻度低） | H18: =H$13/G$13*G18 -> 0 | K18: =G18+I18 -> 0 | L18: =H18+J18 -> 0 | M18: 0.01 | N18: =N$13/M$13*M18 -> 0.30533636 | O18: 0.01 | P18: =P$13/O$13*O18 -> 0.30533636 | Q18: 0.01 | R18: =R$13/Q$13*Q18 -> 0.30533636 | S18: 0.01 | T18: =T$13/S$13*S18 -> 0.30533636 | U18: 0.01 | V18: =V$13/U$13*U18 -> 0.30533636 | W18: 0 | X18: =X$13/W$13*W18 -> 0 | Y18: =M18+O18+Q18+S18+U18+W18 -> 0.05 | Z18: =N18+P18+R18+T18+V18+X18 -> 1.5266818 | AB18: =AB$13/AA$13*AA18 -> 0 | AD18: =AD$13/AC$13*AC18 -> 0 | AF18: =AF$13/AE$13*AE18 -> 0 | AH18: =AH$13/AG$13*AG18 -> 0 | AJ18: =AJ$13/AI$13*AI18 -> 0 | AL18: =AL$13/AK$13*AK18 -> 0 | AM18: =AA18+AC18+AE18+AG18+AK18 -> 0 | AN18: =AB18+AD18+AF18+AH18+AL18 -> 0 | AP18: =AP$13/AO$13*AO18 -> 0 | AQ18: =AO18 -> 0 | AR18: =AP18 -> 0 | AS18: =K18+Y18+AM18+AQ18 -> 0.05 | AT18: =L18+Z18+AN18+AR18 -> 1.5266818 | AU18: - | AV18: =IF(AU18="●",AT18,0) -> 0
C19: 6 | D19: 外注工賃交渉 | F19: 不定期（頻度低） | H19: =H$13/G$13*G19 -> 0 | K19: =G19+I19 -> 0 | L19: =H19+J19 -> 0 | M19: 0.01 | N19: =N$13/M$13*M19 -> 0.30533636 | O19: 0.01 | P19: =P$13/O$13*O19 -> 0.30533636 | Q19: 0.01 | R19: =R$13/Q$13*Q19 -> 0.30533636 | S19: 0.01 | T19: =T$13/S$13*S19 -> 0.30533636 | U19: 0.01 | V19: =V$13/U$13*U19 -> 0.30533636 | W19: 0 | X19: =X$13/W$13*W19 -> 0 | Y19: =M19+O19+Q19+S19+U19+W19 -> 0.05 | Z19: =N19+P19+R19+T19+V19+X19 -> 1.5266818 | AB19: =AB$13/AA$13*AA19 -> 0 | AD19: =AD$13/AC$13*AC19 -> 0 | AF19: =AF$13/AE$13*AE19 -> 0 | AH19: =AH$13/AG$13*AG19 -> 0 | AJ19: =AJ$13/AI$13*AI19 -> 0 | AL19: =AL$13/AK$13*AK19 -> 0 | AM19: =AA19+AC19+AE19+AG19+AK19 -> 0 | AN19: =AB19+AD19+AF19+AH19+AL19 -> 0 | AP19: =AP$13/AO$13*AO19 -> 0 | AQ19: =AO19 -> 0 | AR19: =AP19 -> 0 | AS19: =K19+Y19+AM19+AQ19 -> 0.05 | AT19: =L19+Z19+AN19+AR19 -> 1.5266818 | AU19: - | AV19: =IF(AU19="●",AT19,0) -> 0
B20: AUDIT | C20: 7 | D20: 事前準備 | E20: 提出書類、工場指導 | F20: 不定期（頻度低） | H20: =H$13/G$13*G20 -> 0 | K20: =G20+I20 -> 0 | L20: =H20+J20 -> 0 | M20: 0.01 | N20: =N$13/M$13*M20 -> 0.30533636 | O20: 0.01 | P20: =P$13/O$13*O20 -> 0.30533636 | Q20: 0.01 | R20: =R$13/Q$13*Q20 -> 0.30533636 | S20: 0.01 | T20: =T$13/S$13*S20 -> 0.30533636 | U20: 0.01 | V20: =V$13/U$13*U20 -> 0.30533636 | W20: 0.01 | X20: =X$13/W$13*W20 -> 0.30533636 | Y20: =M20+O20+Q20+S20+U20+W20 -> 0.06 | Z20: =N20+P20+R20+T20+V20+X20 -> 1.8320182 | AB20: =AB$13/AA$13*AA20 -> 0 | AD20: =AD$13/AC$13*AC20 -> 0 | AF20: =AF$13/AE$13*AE20 -> 0 | AH20: =AH$13/AG$13*AG20 -> 0 | AJ20: =AJ$13/AI$13*AI20 -> 0 | AL20: =AL$13/AK$13*AK20 -> 0 | AM20: =AA20+AC20+AE20+AG20+AK20 -> 0 | AN20: =AB20+AD20+AF20+AH20+AL20 -> 0 | AP20: =AP$13/AO$13*AO20 -> 0 | AQ20: =AO20 -> 0 | AR20: =AP20 -> 0 | AS20: =K20+Y20+AM20+AQ20 -> 0.06 | AT20: =L20+Z20+AN20+AR20 -> 1.8320182 | AU20: - | AV20: =IF(AU20="●",AT20,0) -> 0
B21: ※１ | C21: 8 | D21: 当日対応 | F21: 不定期（頻度低） | H21: =H$13/G$13*G21 -> 0 | K21: =G21+I21 -> 0 | L21: =H21+J21 -> 0 | M21: 0.01 | N21: =N$13/M$13*M21 -> 0.30533636 | O21: 0.01 | P21: =P$13/O$13*O21 -> 0.30533636 | Q21: 0.01 | R21: =R$13/Q$13*Q21 -> 0.30533636 | S21: 0.01 | T21: =T$13/S$13*S21 -> 0.30533636 | U21: 0.01 | V21: =V$13/U$13*U21 -> 0.30533636 | W21: 0.01 | X21: =X$13/W$13*W21 -> 0.30533636 | Y21: =M21+O21+Q21+S21+U21+W21 -> 0.06 | Z21: =N21+P21+R21+T21+V21+X21 -> 1.8320182 | AB21: =AB$13/AA$13*AA21 -> 0 | AD21: =AD$13/AC$13*AC21 -> 0 | AF21: =AF$13/AE$13*AE21 -> 0 | AH21: =AH$13/AG$13*AG21 -> 0 | AJ21: =AJ$13/AI$13*AI21 -> 0 | AL21: =AL$13/AK$13*AK21 -> 0 | AM21: =AA21+AC21+AE21+AG21+AK21 -> 0 | AN21: =AB21+AD21+AF21+AH21+AL21 -> 0 | AP21: =AP$13/AO$13*AO21 -> 0 | AQ21: =AO21 -> 0 | AR21: =AP21 -> 0 | AS21: =K21+Y21+AM21+AQ21 -> 0.06 | AT21: =L21+Z21+AN21+AR21 -> 1.8320182 | AU21: - | AV21: =IF(AU21="●",AT21,0) -> 0
B22: 来客、 | C22: 9 | D22: 移動 | E22: 車、ホテル手配 | F22: 不定期（頻度高） | H22: =H$13/G$13*G22 -> 0 | K22: =G22+I22 -> 0 | L22: =H22+J22 -> 0 | M22: 0 | N22: =N$13/M$13*M22 -> 0 | O22: 0.01 | P22: =P$13/O$13*O22 -> 0.30533636 | Q22: 0.01 | R22: =R$13/Q$13*Q22 -> 0.30533636 | S22: 0.01 | T22: =T$13/S$13*S22 -> 0.30533636 | U22: 0.01 | V22: =V$13/U$13*U22 -> 0.30533636 | W22: 0.01 | X22: =X$13/W$13*W22 -> 0.30533636 | Y22: =M22+O22+Q22+S22+U22+W22 -> 0.05 | Z22: =N22+P22+R22+T22+V22+X22 -> 1.5266818 | AB22: =AB$13/AA$13*AA22 -> 0 | AD22: =AD$13/AC$13*AC22 -> 0 | AF22: =AF$13/AE$13*AE22 -> 0 | AH22: =AH$13/AG$13*AG22 -> 0 | AJ22: =AJ$13/AI$13*AI22 -> 0 | AL22: =AL$13/AK$13*AK22 -> 0 | AM22: =AA22+AC22+AE22+AG22+AK22 -> 0 | AN22: =AB22+AD22+AF22+AH22+AL22 -> 0 | AO22: 0.5 | AP22: =AP$13/AO$13*AO22 -> 45.75 | AQ22: =AO22 -> 0.5 | AR22: =AP22 -> 45.75 | AS22: =K22+Y22+AM22+AQ22 -> 0.55 | AT22: =L22+Z22+AN22+AR22 -> 47.276682 | AU22: - | AV22: =IF(AU22="●",AT22,0) -> 0
B23: 出張対応 | C23: 10 | D23: 工場アテンド | E23: 案内、食事 | F23: 不定期（頻度低） | H23: =H$13/G$13*G23 -> 0 | K23: =G23+I23 -> 0 | L23: =H23+J23 -> 0 | M23: 0.02 | N23: =N$13/M$13*M23 -> 0.61067273 | O23: 0.01 | P23: =P$13/O$13*O23 -> 0.30533636 | Q23: 0.01 | R23: =R$13/Q$13*Q23 -> 0.30533636 | S23: 0.01 | T23: =T$13/S$13*S23 -> 0.30533636 | U23: 0.01 | V23: =V$13/U$13*U23 -> 0.30533636 | W23: 0.01 | X23: =X$13/W$13*W23 -> 0.30533636 | Y23: =M23+O23+Q23+S23+U23+W23 -> 0.07 | Z23: =N23+P23+R23+T23+V23+X23 -> 2.1373545 | AB23: =AB$13/AA$13*AA23 -> 0 | AD23: =AD$13/AC$13*AC23 -> 0 | AF23: =AF$13/AE$13*AE23 -> 0 | AH23: =AH$13/AG$13*AG23 -> 0 | AJ23: =AJ$13/AI$13*AI23 -> 0 | AL23: =AL$13/AK$13*AK23 -> 0 | AM23: =AA23+AC23+AE23+AG23+AK23 -> 0 | AN23: =AB23+AD23+AF23+AH23+AL23 -> 0 | AO23: 0.5 | AP23: =AP$13/AO$13*AO23 -> 45.75 | AQ23: =AO23 -> 0.5 | AR23: =AP23 -> 45.75 | AS23: =K23+Y23+AM23+AQ23 -> 0.57 | AT23: =L23+Z23+AN23+AR23 -> 47.887355 | AU23: - | AV23: =IF(AU23="●",AT23,0) -> 0
C24: 11 | D24: 安全管理 | E24: 行程把握、緊急時対応 | F24: 不定期（頻度高） | H24: =H$13/G$13*G24 -> 0 | K24: =G24+I24 -> 0 | L24: =H24+J24 -> 0 | M24: 0.01 | N24: =N$13/M$13*M24 -> 0.30533636 | O24: 0.01 | P24: =P$13/O$13*O24 -> 0.30533636 | Q24: 0.01 | R24: =R$13/Q$13*Q24 -> 0.30533636 | S24: 0.01 | T24: =T$13/S$13*S24 -> 0.30533636 | U24: 0.01 | V24: =V$13/U$13*U24 -> 0.30533636 | W24: 0.01 | X24: =X$13/W$13*W24 -> 0.30533636 | Y24: =M24+O24+Q24+S24+U24+W24 -> 0.06 | Z24: =N24+P24+R24+T24+V24+X24 -> 1.8320182 | AB24: =AB$13/AA$13*AA24 -> 0 | AD24: =AD$13/AC$13*AC24 -> 0 | AF24: =AF$13/AE$13*AE24 -> 0 | AH24: =AH$13/AG$13*AG24 -> 0 | AJ24: =AJ$13/AI$13*AI24 -> 0 | AL24: =AL$13/AK$13*AK24 -> 0 | AM24: =AA24+AC24+AE24+AG24+AK24 -> 0 | AN24: =AB24+AD24+AF24+AH24+AL24 -> 0 | AP24: =AP$13/AO$13*AO24 -> 0 | AQ24: =AO24 -> 0 | AR24: =AP24 -> 0 | AS24: =K24+Y24+AM24+AQ24 -> 0.06 | AT24: =L24+Z24+AN24+AR24 -> 1.8320182 | AU24: - | AV24: =IF(AU24="●",AT24,0) -> 0
A25: 企画 | B25: 開発 | C25: 12 | D25: 商品開発 | E25: 新規素材、加工技術調査、サンプル試作 | F25: 不定期（頻度中） | H25: =H$13/G$13*G25 -> 0 | K25: =G25+I25 -> 0 | L25: =H25+J25 -> 0 | M25: 0 | N25: =N$13/M$13*M25 -> 0 | P25: =P$13/O$13*O25 -> 0 | R25: =R$13/Q$13*Q25 -> 0 | T25: =T$13/S$13*S25 -> 0 | V25: =V$13/U$13*U25 -> 0 | X25: =X$13/W$13*W25 -> 0 | Y25: =M25+O25+Q25+S25+U25+W25 -> 0 | Z25: =N25+P25+R25+T25+V25+X25 -> 0 | AB25: =AB$13/AA$13*AA25 -> 0 | AD25: =AD$13/AC$13*AC25 -> 0 | AF25: =AF$13/AE$13*AE25 -> 0 | AH25: =AH$13/AG$13*AG25 -> 0 | AJ25: =AJ$13/AI$13*AI25 -> 0 | AK25: 0.01 | AL25: =AL$13/AK$13*AK25 -> 0.30533636 | AM25: =AA25+AC25+AE25+AG25+AK25 -> 0.01 | AN25: =AB25+AD25+AF25+AH25+AL25 -> 0.30533636 | AP25: =AP$13/AO$13*AO25 -> 0 | AQ25: =AO25 -> 0 | AR25: =AP25 -> 0 | AS25: =K25+Y25+AM25+AQ25 -> 0.01 | AT25: =L25+Z25+AN25+AR25 -> 0.30533636 | AU25: ● | AV25: =IF(AU25="●",AT25,0) -> 0.30533636
C26: 13 | D26: 加工技術 | E26: パターン自動機設計、パターンシマ改善提案 | F26: 不定期（頻度中） | H26: =H$13/G$13*G26 -> 0 | K26: =G26+I26 -> 0 | L26: =H26+J26 -> 0 | N26: =N$13/M$13*M26 -> 0 | P26: =P$13/O$13*O26 -> 0 | R26: =R$13/Q$13*Q26 -> 0 | T26: =T$13/S$13*S26 -> 0 | V26: =V$13/U$13*U26 -> 0 | X26: =X$13/W$13*W26 -> 0 | Y26: =M26+O26+Q26+S26+U26+W26 -> 0 | Z26: =N26+P26+R26+T26+V26+X26 -> 0 | AA26: 0.01 | AB26: =AB$13/AA$13*AA26 -> 0.30533636 | AC26: 0.01 | AD26: =AD$13/AC$13*AC26 -> 0.30533636 | AE26: 0.01 | AF26: =AF$13/AE$13*AE26 -> 0.30533636 | AG26: 0.01 | AH26: =AH$13/AG$13*AG26 -> 0.30533636 | AJ26: =AJ$13/AI$13*AI26 -> 0 | AK26: 0.01 | AL26: =AL$13/AK$13*AK26 -> 0.30533636 | AM26: =AA26+AC26+AE26+AG26+AK26 -> 0.05 | AN26: =AB26+AD26+AF26+AH26+AL26 -> 1.5266818 | AP26: =AP$13/AO$13*AO26 -> 0 | AQ26: =AO26 -> 0 | AR26: =AP26 -> 0 | AS26: =K26+Y26+AM26+AQ26 -> 0.05 | AT26: =L26+Z26+AN26+AR26 -> 1.5266818 | AU26: ● | AV26: =IF(AU26="●",AT26,0) -> 1.5266818
C27: 14 | D27: 生産技術 | E27: 生産ラインのレイアウト設定提案 | F27: 不定期（頻度低） | H27: =H$13/G$13*G27 -> 0 | K27: =G27+I27 -> 0 | L27: =H27+J27 -> 0 | M27: 0.01 | N27: =N$13/M$13*M27 -> 0.30533636 | P27: =P$13/O$13*O27 -> 0 | R27: =R$13/Q$13*Q27 -> 0 | T27: =T$13/S$13*S27 -> 0 | V27: =V$13/U$13*U27 -> 0 | X27: =X$13/W$13*W27 -> 0 | Y27: =M27+O27+Q27+S27+U27+W27 -> 0.01 | Z27: =N27+P27+R27+T27+V27+X27 -> 0.30533636 | AA27: 0.01 | AB27: =AB$13/AA$13*AA27 -> 0.30533636 | AC27: 0.01 | AD27: =AD$13/AC$13*AC27 -> 0.30533636 | AE27: 0.01 | AF27: =AF$13/AE$13*AE27 -> 0.30533636 | AG27: 0.01 | AH27: =AH$13/AG$13*AG27 -> 0.30533636 | AJ27: =AJ$13/AI$13*AI27 -> 0 | AK27: 0.01 | AL27: =AL$13/AK$13*AK27 -> 0.30533636 | AM27: =AA27+AC27+AE27+AG27+AK27 -> 0.05 | AN27: =AB27+AD27+AF27+AH27+AL27 -> 1.5266818 | AP27: =AP$13/AO$13*AO27 -> 0 | AQ27: =AO27 -> 0 | AR27: =AP27 -> 0 | AS27: =K27+Y27+AM27+AQ27 -> 0.06 | AT27: =L27+Z27+AN27+AR27 -> 1.8320182 | AU27: ● | AV27: =IF(AU27="●",AT27,0) -> 1.8320182
C28: 15 | D28: 管理技術 | E28: 工程分析、進捗ばらつき、QC管理手法 | F28: 不定期（頻度中） | H28: =H$13/G$13*G28 -> 0 | K28: =G28+I28 -> 0 | L28: =H28+J28 -> 0 | M28: 0.01 | N28: =N$13/M$13*M28 -> 0.30533636 | P28: =P$13/O$13*O28 -> 0 | R28: =R$13/Q$13*Q28 -> 0 | T28: =T$13/S$13*S28 -> 0 | V28: =V$13/U$13*U28 -> 0 | X28: =X$13/W$13*W28 -> 0 | Y28: =M28+O28+Q28+S28+U28+W28 -> 0.01 | Z28: =N28+P28+R28+T28+V28+X28 -> 0.30533636 | AB28: =AB$13/AA$13*AA28 -> 0 | AD28: =AD$13/AC$13*AC28 -> 0 | AF28: =AF$13/AE$13*AE28 -> 0 | AH28: =AH$13/AG$13*AG28 -> 0 | AJ28: =AJ$13/AI$13*AI28 -> 0 | AK28: 0.07 | AL28: =AL$13/AK$13*AK28 -> 2.1373545 | AM28: =AA28+AC28+AE28+AG28+AK28 -> 0.07 | AN28: =AB28+AD28+AF28+AH28+AL28 -> 2.1373545 | AP28: =AP$13/AO$13*AO28 -> 0 | AQ28: =AO28 -> 0 | AR28: =AP28 -> 0 | AS28: =K28+Y28+AM28+AQ28 -> 0.08 | AT28: =L28+Z28+AN28+AR28 -> 2.4426909 | AU28: - | AV28: =IF(AU28="●",AT28,0) -> 0
C29: 16 | D29: 評価技術 | E29: 機能性評価、商品評価、物性試験等 | F29: 不定期（頻度中） | H29: =H$13/G$13*G29 -> 0 | K29: =G29+I29 -> 0 | L29: =H29+J29 -> 0 | M29: 0.01 | N29: =N$13/M$13*M29 -> 0.30533636 | P29: =P$13/O$13*O29 -> 0 | R29: =R$13/Q$13*Q29 -> 0 | T29: =T$13/S$13*S29 -> 0 | V29: =V$13/U$13*U29 -> 0 | X29: =X$13/W$13*W29 -> 0 | Y29: =M29+O29+Q29+S29+U29+W29 -> 0.01 | Z29: =N29+P29+R29+T29+V29+X29 -> 0.30533636 | AB29: =AB$13/AA$13*AA29 -> 0 | AD29: =AD$13/AC$13*AC29 -> 0 | AF29: =AF$13/AE$13*AE29 -> 0 | AH29: =AH$13/AG$13*AG29 -> 0 | AJ29: =AJ$13/AI$13*AI29 -> 0 | AK29: 0.01 | AL29: =AL$13/AK$13*AK29 -> 0.30533636 | AM29: =AA29+AC29+AE29+AG29+AK29 -> 0.01 | AN29: =AB29+AD29+AF29+AH29+AL29 -> 0.30533636 | AP29: =AP$13/AO$13*AO29 -> 0 | AQ29: =AO29 -> 0 | AR29: =AP29 -> 0 | AS29: =K29+Y29+AM29+AQ29 -> 0.02 | AT29: =L29+Z29+AN29+AR29 -> 0.61067273 | AU29: ● | AV29: =IF(AU29="●",AT29,0) -> 0.61067273
A30: 前段取り | B30: 生産計画 | C30: 17 | D30: プランテーブル | E30: 長期生産計画 | F30: 週次 | G30: 0.05 | H30: =H$13/G$13*G30 -> 9.0375 | K30: =G30+I30 -> 0.05 | L30: =H30+J30 -> 9.0375 | M30: 0.02 | N30: =N$13/M$13*M30 -> 0.61067273 | P30: =P$13/O$13*O30 -> 0 | R30: =R$13/Q$13*Q30 -> 0 | T30: =T$13/S$13*S30 -> 0 | V30: =V$13/U$13*U30 -> 0 | X30: =X$13/W$13*W30 -> 0 | Y30: =M30+O30+Q30+S30+U30+W30 -> 0.02 | Z30: =N30+P30+R30+T30+V30+X30 -> 0.61067273 | AB30: =AB$13/AA$13*AA30 -> 0 | AD30: =AD$13/AC$13*AC30 -> 0 | AF30: =AF$13/AE$13*AE30 -> 0 | AH30: =AH$13/AG$13*AG30 -> 0 | AJ30: =AJ$13/AI$13*AI30 -> 0 | AL30: =AL$13/AK$13*AK30 -> 0 | AM30: =AA30+AC30+AE30+AG30+AK30 -> 0 | AN30: =AB30+AD30+AF30+AH30+AL30 -> 0 | AP30: =AP$13/AO$13*AO30 -> 0 | AQ30: =AO30 -> 0 | AR30: =AP30 -> 0 | AS30: =K30+Y30+AM30+AQ30 -> 0.07 | AT30: =L30+Z30+AN30+AR30 -> 9.6481727 | AU30: - | AV30: =IF(AU30="●",AT30,0) -> 0
C31: 18 | D31: 明細連絡 | E31: SKU明細を工場へ連絡する | F31: 日次 | H31: =H$13/G$13*G31 -> 0 | K31: =G31+I31 -> 0 | L31: =H31+J31 -> 0 | M31: 0.01 | N31: =N$13/M$13*M31 -> 0.30533636 | O31: 0.01 | P31: =P$13/O$13*O31 -> 0.30533636 | Q31: 0.01 | R31: =R$13/Q$13*Q31 -> 0.30533636 | S31: 0.01 | T31: =T$13/S$13*S31 -> 0.30533636 | U31: 0.01 | V31: =V$13/U$13*U31 -> 0.30533636 | W31: 0.01 | X31: =X$13/W$13*W31 -> 0.30533636 | Y31: =M31+O31+Q31+S31+U31+W31 -> 0.06 | Z31: =N31+P31+R31+T31+V31+X31 -> 1.8320182 | AB31: =AB$13/AA$13*AA31 -> 0 | AD31: =AD$13/AC$13*AC31 -> 0 | AF31: =AF$13/AE$13*AE31 -> 0 | AH31: =AH$13/AG$13*AG31 -> 0 | AJ31: =AJ$13/AI$13*AI31 -> 0 | AL31: =AL$13/AK$13*AK31 -> 0 | AM31: =AA31+AC31+AE31+AG31+AK31 -> 0 | AN31: =AB31+AD31+AF31+AH31+AL31 -> 0 | AP31: =AP$13/AO$13*AO31 -> 0 | AQ31: =AO31 -> 0 | AR31: =AP31 -> 0 | AS31: =K31+Y31+AM31+AQ31 -> 0.06 | AT31: =L31+Z31+AN31+AR31 -> 1.8320182 | AU31: - | AV31: =IF(AU31="●",AT31,0) -> 0
C32: 19 | D32: 工場生産計画 | E32: 中期生産計画 | F32: 週次 | G32: 0.05 | H32: =H$13/G$13*G32 -> 9.0375 | K32: =G32+I32 -> 0.05 | L32: =H32+J32 -> 9.0375 | M32: 0.01 | N32: =N$13/M$13*M32 -> 0.30533636 | O32: 0.01 | P32: =P$13/O$13*O32 -> 0.30533636 | R32: =R$13/Q$13*Q32 -> 0 | T32: =T$13/S$13*S32 -> 0 | V32: =V$13/U$13*U32 -> 0 | X32: =X$13/W$13*W32 -> 0 | Y32: =M32+O32+Q32+S32+U32+W32 -> 0.02 | Z32: =N32+P32+R32+T32+V32+X32 -> 0.61067273 | AB32: =AB$13/AA$13*AA32 -> 0 | AD32: =AD$13/AC$13*AC32 -> 0 | AF32: =AF$13/AE$13*AE32 -> 0 | AH32: =AH$13/AG$13*AG32 -> 0 | AJ32: =AJ$13/AI$13*AI32 -> 0 | AL32: =AL$13/AK$13*AK32 -> 0 | AM32: =AA32+AC32+AE32+AG32+AK32 -> 0 | AN32: =AB32+AD32+AF32+AH32+AL32 -> 0 | AP32: =AP$13/AO$13*AO32 -> 0 | AQ32: =AO32 -> 0 | AR32: =AP32 -> 0 | AS32: =K32+Y32+AM32+AQ32 -> 0.07 | AT32: =L32+Z32+AN32+AR32 -> 9.6481727 | AU32: - | AV32: =IF(AU32="●",AT32,0) -> 0
C33: 20 | D33: 資材進捗 | E33: 材料の進捗状況を確認し工場へ報告する | F33: 日次 | H33: =H$13/G$13*G33 -> 0 | K33: =G33+I33 -> 0 | L33: =H33+J33 -> 0 | M33: 0 | N33: =N$13/M$13*M33 -> 0 | O33: 0.01 | P33: =P$13/O$13*O33 -> 0.30533636 | Q33: 0.01 | R33: =R$13/Q$13*Q33 -> 0.30533636 | S33: 0.01 | T33: =T$13/S$13*S33 -> 0.30533636 | U33: 0.01 | V33: =V$13/U$13*U33 -> 0.30533636 | W33: 0.01 | X33: =X$13/W$13*W33 -> 0.30533636 | Y33: =M33+O33+Q33+S33+U33+W33 -> 0.05 | Z33: =N33+P33+R33+T33+V33+X33 -> 1.5266818 | AB33: =AB$13/AA$13*AA33 -> 0 | AD33: =AD$13/AC$13*AC33 -> 0 | AF33: =AF$13/AE$13*AE33 -> 0 | AH33: =AH$13/AG$13*AG33 -> 0 | AJ33: =AJ$13/AI$13*AI33 -> 0 | AL33: =AL$13/AK$13*AK33 -> 0 | AM33: =AA33+AC33+AE33+AG33+AK33 -> 0 | AN33: =AB33+AD33+AF33+AH33+AL33 -> 0 | AP33: =AP$13/AO$13*AO33 -> 0 | AQ33: =AO33 -> 0 | AR33: =AP33 -> 0 | AS33: =K33+Y33+AM33+AQ33 -> 0.05 | AT33: =L33+Z33+AN33+AR33 -> 1.5266818 | AU33: - | AV33: =IF(AU33="●",AT33,0) -> 0
C34: 21 | D34: 注意連絡 | E34: 特別に注視する内容を工場へ連絡 | F34: 週次 | H34: =H$13/G$13*G34 -> 0 | K34: =G34+I34 -> 0 | L34: =H34+J34 -> 0 | M34: 0.01 | N34: =N$13/M$13*M34 -> 0.30533636 | O34: 0.01 | P34: =P$13/O$13*O34 -> 0.30533636 | Q34: 0.01 | R34: =R$13/Q$13*Q34 -> 0.30533636 | S34: 0.01 | T34: =T$13/S$13*S34 -> 0.30533636 | U34: 0.01 | V34: =V$13/U$13*U34 -> 0.30533636 | W34: 0.01 | X34: =X$13/W$13*W34 -> 0.30533636 | Y34: =M34+O34+Q34+S34+U34+W34 -> 0.06 | Z34: =N34+P34+R34+T34+V34+X34 -> 1.8320182 | AA34: 0.02 | AB34: =AB$13/AA$13*AA34 -> 0.61067273 | AC34: 0.04 | AD34: =AD$13/AC$13*AC34 -> 1.2213455 | AE34: 0.02 | AF34: =AF$13/AE$13*AE34 -> 0.61067273 | AG34: 0.02 | AH34: =AH$13/AG$13*AG34 -> 0.61067273 | AI34: 0.02 | AJ34: =AJ$13/AI$13*AI34 -> 0.61067273 | AL34: =AL$13/AK$13*AK34 -> 0 | AM34: =AA34+AC34+AE34+AG34+AK34 -> 0.1 | AN34: =AB34+AD34+AF34+AH34+AL34 -> 3.0533636 | AP34: =AP$13/AO$13*AO34 -> 0 | AQ34: =AO34 -> 0 | AR34: =AP34 -> 0 | AS34: =K34+Y34+AM34+AQ34 -> 0.16 | AT34: =L34+Z34+AN34+AR34 -> 4.8853818 | AU34: - | AV34: =IF(AU34="●",AT34,0) -> 0
B35: サンプル | C35: 22 | D35: 受注 | E35: 営業オーダー受注。サンプル管理表への記入 | F35: 日次 | H35: =H$13/G$13*G35 -> 0 | K35: =G35+I35 -> 0 | L35: =H35+J35 -> 0 | M35: 0.01 | N35: =N$13/M$13*M35 -> 0.30533636 | O35: 0.01 | P35: =P$13/O$13*O35 -> 0.30533636 | Q35: 0.01 | R35: =R$13/Q$13*Q35 -> 0.30533636 | S35: 0.01 | T35: =T$13/S$13*S35 -> 0.30533636 | U35: 0.01 | V35: =V$13/U$13*U35 -> 0.30533636 | W35: 0.01 | X35: =X$13/W$13*W35 -> 0.30533636 | Y35: =M35+O35+Q35+S35+U35+W35 -> 0.06 | Z35: =N35+P35+R35+T35+V35+X35 -> 1.8320182 | AB35: =AB$13/AA$13*AA35 -> 0 | AD35: =AD$13/AC$13*AC35 -> 0 | AF35: =AF$13/AE$13*AE35 -> 0 | AH35: =AH$13/AG$13*AG35 -> 0 | AJ35: =AJ$13/AI$13*AI35 -> 0 | AL35: =AL$13/AK$13*AK35 -> 0 | AM35: =AA35+AC35+AE35+AG35+AK35 -> 0 | AN35: =AB35+AD35+AF35+AH35+AL35 -> 0 | AP35: =AP$13/AO$13*AO35 -> 0 | AQ35: =AO35 -> 0 | AR35: =AP35 -> 0 | AS35: =K35+Y35+AM35+AQ35 -> 0.06 | AT35: =L35+Z35+AN35+AR35 -> 1.8320182 | AU35: - | AV35: =IF(AU35="●",AT35,0) -> 0
C36: 23 | D36: 工場指示 | E36: 日本からのサンプル依頼を工場へ連絡 | F36: 日次 | H36: =H$13/G$13*G36 -> 0 | K36: =G36+I36 -> 0 | L36: =H36+J36 -> 0 | M36: 0.01 | N36: =N$13/M$13*M36 -> 0.30533636 | O36: 0.01 | P36: =P$13/O$13*O36 -> 0.30533636 | Q36: 0.01 | R36: =R$13/Q$13*Q36 -> 0.30533636 | S36: 0.01 | T36: =T$13/S$13*S36 -> 0.30533636 | U36: 0.01 | V36: =V$13/U$13*U36 -> 0.30533636 | W36: 0.01 | X36: =X$13/W$13*W36 -> 0.30533636 | Y36: =M36+O36+Q36+S36+U36+W36 -> 0.06 | Z36: =N36+P36+R36+T36+V36+X36 -> 1.8320182 | AB36: =AB$13/AA$13*AA36 -> 0 | AD36: =AD$13/AC$13*AC36 -> 0 | AF36: =AF$13/AE$13*AE36 -> 0 | AH36: =AH$13/AG$13*AG36 -> 0 | AJ36: =AJ$13/AI$13*AI36 -> 0 | AL36: =AL$13/AK$13*AK36 -> 0 | AM36: =AA36+AC36+AE36+AG36+AK36 -> 0 | AN36: =AB36+AD36+AF36+AH36+AL36 -> 0 | AP36: =AP$13/AO$13*AO36 -> 0 | AQ36: =AO36 -> 0 | AR36: =AP36 -> 0 | AS36: =K36+Y36+AM36+AQ36 -> 0.06 | AT36: =L36+Z36+AN36+AR36 -> 1.8320182 | AU36: - | AV36: =IF(AU36="●",AT36,0) -> 0
C37: 24 | D37: 納期回答 | E37: 工場スケジューリング、納期回答 | F37: 日次 | H37: =H$13/G$13*G37 -> 0 | K37: =G37+I37 -> 0 | L37: =H37+J37 -> 0 | M37: 0.01 | N37: =N$13/M$13*M37 -> 0.30533636 | O37: 0.01 | P37: =P$13/O$13*O37 -> 0.30533636 | Q37: 0.01 | R37: =R$13/Q$13*Q37 -> 0.30533636 | S37: 0.01 | T37: =T$13/S$13*S37 -> 0.30533636 | U37: 0.01 | V37: =V$13/U$13*U37 -> 0.30533636 | W37: 0.01 | X37: =X$13/W$13*W37 -> 0.30533636 | Y37: =M37+O37+Q37+S37+U37+W37 -> 0.06 | Z37: =N37+P37+R37+T37+V37+X37 -> 1.8320182 | AB37: =AB$13/AA$13*AA37 -> 0 | AD37: =AD$13/AC$13*AC37 -> 0 | AF37: =AF$13/AE$13*AE37 -> 0 | AH37: =AH$13/AG$13*AG37 -> 0 | AJ37: =AJ$13/AI$13*AI37 -> 0 | AL37: =AL$13/AK$13*AK37 -> 0 | AM37: =AA37+AC37+AE37+AG37+AK37 -> 0 | AN37: =AB37+AD37+AF37+AH37+AL37 -> 0 | AP37: =AP$13/AO$13*AO37 -> 0 | AQ37: =AO37 -> 0 | AR37: =AP37 -> 0 | AS37: =K37+Y37+AM37+AQ37 -> 0.06 | AT37: =L37+Z37+AN37+AR37 -> 1.8320182 | AU37: - | AV37: =IF(AU37="●",AT37,0) -> 0
C38: 25 | D38: 仕様 | E38: 仕様書の受領、翻訳 | F38: 日次 | H38: =H$13/G$13*G38 -> 0 | K38: =G38+I38 -> 0 | L38: =H38+J38 -> 0 | M38: 0.07 | N38: =N$13/M$13*M38 -> 2.1373545 | O38: 0.26 | P38: =P$13/O$13*O38 -> 7.9387455 | Q38: 0.25 | R38: =R$13/Q$13*Q38 -> 7.6334091 | S38: 0.2 | T38: =T$13/S$13*S38 -> 6.1067273 | U38: 0.25 | V38: =V$13/U$13*U38 -> 7.6334091 | W38: 0.19 | X38: =X$13/W$13*W38 -> 5.8013909 | Y38: =M38+O38+Q38+S38+U38+W38 -> 1.22 | Z38: =N38+P38+R38+T38+V38+X38 -> 37.251036 | AB38: =AB$13/AA$13*AA38 -> 0 | AD38: =AD$13/AC$13*AC38 -> 0 | AF38: =AF$13/AE$13*AE38 -> 0 | AH38: =AH$13/AG$13*AG38 -> 0 | AJ38: =AJ$13/AI$13*AI38 -> 0 | AL38: =AL$13/AK$13*AK38 -> 0 | AM38: =AA38+AC38+AE38+AG38+AK38 -> 0 | AN38: =AB38+AD38+AF38+AH38+AL38 -> 0 | AP38: =AP$13/AO$13*AO38 -> 0 | AQ38: =AO38 -> 0 | AR38: =AP38 -> 0 | AS38: =K38+Y38+AM38+AQ38 -> 1.22 | AT38: =L38+Z38+AN38+AR38 -> 37.251036 | AU38: - | AV38: =IF(AU38="●",AT38,0) -> 0
C39: 26 | D39: パターンチェック | E39: パターンの受領、寸法チェック | F39: 日次 | H39: =H$13/G$13*G39 -> 0 | K39: =G39+I39 -> 0 | L39: =H39+J39 -> 0 | N39: =N$13/M$13*M39 -> 0 | P39: =P$13/O$13*O39 -> 0 | R39: =R$13/Q$13*Q39 -> 0 | T39: =T$13/S$13*S39 -> 0 | V39: =V$13/U$13*U39 -> 0 | X39: =X$13/W$13*W39 -> 0 | Y39: =M39+O39+Q39+S39+U39+W39 -> 0 | Z39: =N39+P39+R39+T39+V39+X39 -> 0 | AA39: 0.01 | AB39: =AB$13/AA$13*AA39 -> 0.30533636 | AC39: 0.01 | AD39: =AD$13/AC$13*AC39 -> 0.30533636 | AE39: 0.01 | AF39: =AF$13/AE$13*AE39 -> 0.30533636 | AG39: 0.02 | AH39: =AH$13/AG$13*AG39 -> 0.61067273 | AI39: 0.01 | AJ39: =AJ$13/AI$13*AI39 -> 0.30533636 | AK39: 0.03 | AL39: =AL$13/AK$13*AK39 -> 0.91600909 | AM39: =AA39+AC39+AE39+AG39+AK39 -> 0.08 | AN39: =AB39+AD39+AF39+AH39+AL39 -> 2.4426909 | AP39: =AP$13/AO$13*AO39 -> 0 | AQ39: =AO39 -> 0 | AR39: =AP39 -> 0 | AS39: =K39+Y39+AM39+AQ39 -> 0.08 | AT39: =L39+Z39+AN39+AR39 -> 2.4426909 | AU39: - | AV39: =IF(AU39="●",AT39,0) -> 0
